Workbook

Sheet (旧)ﾍﾞﾝﾀﾞｰ小型
A1: Ｓｅｒ． | B1: 生産月 | C1: Ｎｏ． | D1: 機種名 | E1: 顧客 | F1: 仕様機種名 | G1: 仕様分類 | H1: 機種品番 | I1: 確定仕様書NO | J1: 着手日 | K1: 完成予定日
A3: TS13329056 | B3: 09月 | C3: 001 | D3: EGB1303ARE_EXP | E3: ＡＭＡＤＡ ＡＭＥＲＩＣＡ ＩＮＣ． | F3: EGB1303ARE-E | G3: STD | H3: 0E1859 | I3: BDA1314 | J3: 2026/08/01 | K3: 2026/09/08
A4: TS13399252 | B4: 09月 | C4: 002 | D4: EGB1303AE_EXP | E4: Ａｍａｄａ Ｏｃｅａｎｉａ Ｐｔｙ Ｌｔ | F4: EGB1303AE-E | G4: STD | H4: 0E1243 | I4: OCE0062 | J4: 2026/08/05 | K4: 2026/09/02
A5: TS13399247 | B5: 09月 | C5: 003 | D5: EGB1303AE | E5: （株）アマダベンディングＳ部 | F5: EGB1303AE-J | G5: STD | H5: 0D9621 | J5: 2026/08/06 | K5: 2026/09/03
A6: TS62077151 | B6: 09月 | C6: 004 | D6: EGB6020E_EXP | E6: ＡＭＡＤＡ ＡＭＥＲＩＣＡ ＩＮＣ． | F6: EGB6020E-E | G6: LZS+BIS+AF | H6: 0D7905 | I6: BDA1290 | J6: 2026/08/06 | K6: 2026/08/29
A7: TS13399248 | B7: 09月 | C7: 005 | D7: EGB1303AE | E7: （株）アマダベンディングＳ部 | F7: EGB1303AE-J | G7: STD | H7: 0D9621 | J7: 2026/08/08 | K7: 2026/09/05
A8: TS13377319 | B8: 09月 | C8: 006 | D8: EGB1303E_EXP | E8: ＡＭＡＤＡ ＣＡＮＡＤＡ ＬＴＤ． | F8: EGB1303E-E | G8: LZS+BIS+AF | H8: 0D9825 | I8: BDA1315 | J8: 2026/08/08 | K8: 2026/09/02
A9: TS13377320 | B9: 09月 | C9: 007 | D9: EGB1303E_EXP | E9: 【OCEANIA】Fuji Harwal | F9: EGB1303E-E | G9: LZS+BIS+AF | H9: 0D9825 | I9: OCE0061 | J9: 2026/08/08 | K9: 2026/09/02
A10: TS13377310 | B10: 09月 | C10: 008 | D10: EGB1303E | E10: （株）アマダベンディングＳ部 | F10: EGB1303E-J | G10: LZS+BIS | H10: 0D9824 | J10: 2026/08/18 | K10: 2026/09/02
A11: TS62077145 | B11: 09月 | C11: 009 | D11: EGB6020E | E11: （株）朝陽 | F11: EGB6020E-J | G11: LZS+BIS | H11: 0D7255 | I11: 193791 | J11: 2026/08/18 | K11: 2026/09/02
A12: TS62077144 | B12: 09月 | C12: 010 | D12: EGB6020E | F12: EGB6020E-J | G12: LZS+BIS | H12: 0D7255 | I12: 182674 | J12: 2026/08/19 | K12: 2026/09/03
A13: TS60299196 | B13: 09月 | C13: 011 | D13: EGB6020AE_EXP | E13: ＡＭＡＤＡ ＴＡＩＷＡＮ ＩＮＣ． | F13: EGB6020AE-E | G13: STD | H13: 0D8050 | I13: TW0502 | J13: 2026/08/19 | K13: 2026/09/09
A14: TS82577271 | B14: 09月 | C14: 012 | D14: EGB8025E | E14: エアコンスター（株） | F14: EGB8025E-J | G14: LZS+BIS | H14: 0E1240 | I14: 182685 | J14: 2026/08/19 | K14: 2026/09/03
A15: TS60299192 | B15: 09月 | C15: 013 | D15: EGB6020AE | E15: （株）廣澤精機製作所 | F15: EGB6020AE-J | G15: STD | H15: 0D7904 | I15: 193748 | J15: 2026/08/21 | K15: 2026/09/11
A16: TS82577278 | B16: 09月 | C16: 014 | D16: EGB8025E_EXP | E16: アマダアジアパシフィック | F16: EGB8025E-E | G16: LZS+BIS+AF | H16: 0E1858 | I16: ASB0893 | J16: 2026/08/21 | K16: 2026/09/08
A17: TS13399246 | B17: 09月 | C17: 015 | D17: EGB1303AE | E17: （株）廣澤精機製作所 | F17: EGB1303AE-J | G17: STD | H17: 0D9621 | I17: 193750 | J17: 2026/08/22 | K17: 2026/09/15
A18: TS82577269 | B18: 09月 | C18: 016 | D18: EGB8025E | E18: （株）ツカタ | F18: EGB8025E-J | G18: LZS+BIS | H18: 0E1240 | I18: 183633 | J18: 2026/08/22 | K18: 2026/09/08
A19: TS82577277 | B19: 09月 | C19: 017 | D19: EGB8025E_EXP | E19: ＡＭＡＤＡ ＡＭＥＲＩＣＡ ＩＮＣ． | F19: EGB8025E-E | G19: LZS+BIS+AF | H19: 0E1858 | I19: BDA1309 | J19: 2026/08/22 | K19: 2026/09/09
A20: TS13399245 | B20: 09月 | C20: 018 | D20: EGB1303AE | E20: （株）廣澤精機製作所 | F20: EGB1303AE-J | G20: STD | H20: 0D9621 | I20: 193749 | J20: 2026/08/26 | K20: 2026/09/17
A21: TS13377312 | B21: 09月 | C21: 019 | D21: EGB1303E | E21: （株）アマダベンディングＳ部 | F21: EGB1303E-J | G21: LZS+BIS | H21: 0D9824 | J21: 2026/08/26 | K21: 2026/09/11
A22: TS13377321 | B22: 09月 | C22: 020 | D22: EGB1303E_EXP | E22: ＡＭＡＤＡ ＡＭＥＲＩＣＡ ＩＮＣ． | F22: EGB1303E-E | G22: LZS+BIS+AF | H22: 0D9825 | I22: BDA1298 | J22: 2026/08/26 | K22: 2026/09/12
A23: TS13329993 | B23: 09月 | C23: 021 | D23: EGB1303E | F23: EGB1303E-J | G23: STD | H23: 0F5059 | J23: 2026/08/27 | K23: 2026/09/30
A24: TS82577266 | B24: 09月 | C24: 022 | D24: EGB8025E | E24: （株）アマダベンディングＳ部 | F24: EGB8025E-J | G24: LZS+BIS | H24: 0E1240 | J24: 2026/08/27 | K24: 2026/09/12
A25: TS13377322 | B25: 09月 | C25: 023 | D25: EGB1303E_EXP | E25: ＡＭＡＤＡ ＡＭＥＲＩＣＡ ＩＮＣ． | F25: EGB1303E-E | G25: LZS+BIS+AF | H25: 0D9825 | I25: BDA1299 | J25: 2026/08/27 | K25: 2026/09/15
A26: TS82577268 | B26: 09月 | C26: 024 | D26: EGB8025E | E26: エース機工（株） | F26: EGB8025E-J | G26: LZS+BIS | H26: 0E1240 | I26: 193793 | J26: 2026/08/29 | K26: 2026/09/16
A27: TS60299201 | B27: 09月 | C27: 025 | D27: EGB6020AE_CE | E27: 【AESA】AMADA ITALIA (IT 299154) | F27: EGB6020AE-C | G27: STD | H27: 0G3964 | I27: BDE0162 | J27: 2026/08/29 | K27: 2026/09/24
A28: TS82577267 | B28: 09月 | C28: 026 | D28: EGB8025E | E28: （株）アマダベンディングＳ部 | F28: EGB8025E-J | G28: LZS+BIS | H28: 0E1240 | J28: 2026/09/01 | K28: 2026/09/17
A29: TS82577270 | B29: 09月 | C29: 027 | D29: EGB8025E | E29: （株）アマダベンディングＳ部 | F29: EGB8025E-J | G29: LZS+BIS | H29: 0E1240 | J29: 2026/09/01 | K29: 2026/09/17
A30: TS13399255 | B30: 09月 | C30: 028 | D30: EGB1303AE_EXP | E30: ＡＭＡＤＡ ＡＭＥＲＩＣＡ ＩＮＣ． | F30: EGB1303AE-E | G30: STD | H30: 0E1243 | I30: BDA1313 | J30: 2026/09/01 | K30: 2026/09/25
A31: TS13377311 | B31: 09月 | C31: 029 | D31: EGB1303E | E31: （株）アマダベンディングＳ部 | F31: EGB1303E-J | G31: LZS+BIS | H31: 0D9824 | J31: 2026/09/03 | K31: 2026/09/19
A32: TS13377315 | B32: 09月 | C32: 030 | D32: EGB1303E | E32: （株）アマダベンディングＳ部 | F32: EGB1303E-J | G32: LZS+BIS | H32: 0D9824 | J32: 2026/09/03 | K32: 2026/09/19
A33: TS60299202 | B33: 09月 | C33: 031 | D33: EGB6020AE_CE | E33: 【AESA】TAVECCHIO( EX AITALIA) | F33: EGB6020AE-C | G33: STD | H33: 0G3964 | I33: BDE0163 | J33: 2026/09/03 | K33: 2026/09/29
A34: TS62077154 | B34: 09月 | C34: 032 | D34: EGB6020E_EXP | E34: ＡＭＡＤＡ ＡＭＥＲＩＣＡ ＩＮＣ． | F34: EGB6020E-E | G34: LZS+BIS+AF | H34: 0D7905 | I34: BDA1304 | J34: 2026/09/05 | K34: 2026/09/26
A35: TS13377323 | B35: 09月 | C35: 033 | D35: EGB1303E_EXP | E35: ＡＭＡＤＡ ＡＭＥＲＩＣＡ ＩＮＣ． | F35: EGB1303E-E | G35: LZS+BIS+AF | H35: 0D9825 | I35: BDA1300 | J35: 2026/09/05 | K35: 2026/09/26
A36: TS62077153 | B36: 09月 | C36: 034 | D36: EGB6020E_EXP | E36: ＡＭＡＤＡ ＡＭＥＲＩＣＡ ＩＮＣ． | F36: EGB6020E-E | G36: LZS+BIS+AF | H36: 0D7905 | I36: BDA1303 | J36: 2026/09/08 | K36: 2026/09/29
A37: TS62077155 | B37: 09月 | C37: 035 | D37: EGB6020E_EXP | E37: ＡＭＡＤＡ ＡＭＥＲＩＣＡ ＩＮＣ． | F37: EGB6020E-E | G37: LZS+BIS+AF | H37: 0D7905 | I37: BDA1305 | J37: 2026/09/08 | K37: 2026/09/29
A38: TS82577276 | B38: 09月 | C38: 036 | D38: EGB8025E_EXP | E38: ＡＭＡＤＡ ＡＭＥＲＩＣＡ ＩＮＣ． | F38: EGB8025E-E | G38: LZS+BIS+AF | H38: 0E1858 | I38: BDA1308 | J38: 2026/09/09 | K38: 2026/09/30
A39: TS82577279 | B39: 09月 | C39: 037 | D39: EGB8025E_EXP | E39: ＡＭＡＤＡ ＴＡＩＷＡＮ ＩＮＣ． | F39: EGB8025E-E | G39: LZS+BIS+AF | H39: 0E1858 | I39: TW0508 | J39: 2026/09/09 | K39: 2026/09/30
A40: TS13377327 | B40: 10月 | C40: 001 | D40: EGB1303E_EXP | E40: 【ベトナム】Thu？n Nhat | F40: EGB1303E-E | G40: LZS+BIS+AF | H40: 0D9825 | I40: ASB0890 | J40: 2026/09/12 | K40: 2026/09/30
A41: TS62077156 | B41: 10月 | C41: 002 | D41: EGB6020E_EXP | E41: ＡＭＡＤＡ ＡＭＥＲＩＣＡ ＩＮＣ． | F41: EGB6020E-E | G41: LZS+BIS+AF | H41: 0D7905 | I41: BDA1343 | J41: 2026/09/12 | K41: 2026/10/01
...

Sheet (新)ﾍﾞﾝﾀﾞｰ小型
A1: Ｓｅｒ． | B1: 生産月 | C1: Ｎｏ． | D1: 機種名 | E1: 顧客 | F1: 仕様機種名 | G1: 仕様分類 | H1: 機種品番 | I1: 確定仕様書NO | J1: 着手日 | K1: 完成予定日
A3: TS13329056 | B3: 10月 | C3: 001 | D3: EGB1303ARE_EXP | E3: ＡＭＡＤＡ ＡＭＥＲＩＣＡ ＩＮＣ． | F3: EGB1303ARE-E | G3: STD | H3: 0E1859 | I3: BDA1314 | J3: 2026/08/01 | K3: 2026/09/08
A4: TS13399252 | B4: 10月 | C4: 002 | D4: EGB1303AE_EXP | E4: Ａｍａｄａ Ｏｃｅａｎｉａ Ｐｔｙ Ｌｔ | F4: EGB1303AE-E | G4: STD | H4: 0E1243 | I4: OCE0062 | J4: 2026/08/05 | K4: 2026/09/02
A5: TS13399248 | B5: 10月 | C5: 003 | D5: EGB1303AE | E5: （株）アマダベンディングＳ部 | F5: EGB1303AE-J | G5: STD | H5: 0D9621 | J5: 2026/08/08 | K5: 2026/09/04
A6: TS60299196 | B6: 10月 | C6: 004 | D6: EGB6020AE_EXP | E6: ＡＭＡＤＡ ＴＡＩＷＡＮ ＩＮＣ． | F6: EGB6020AE-E | G6: STD | H6: 0D8050 | I6: TW0502 | J6: 2026/08/19 | K6: 2026/09/08
A7: TS13377312 | B7: 10月 | C7: 005 | D7: EGB1303E | E7: （株）アマダベンディングＳ部 | F7: EGB1303E-J | G7: LZS+BIS | H7: 0D9824 | J7: 2026/08/26 | K7: 2026/09/09
A8: TS13377321 | B8: 10月 | C8: 006 | D8: EGB1303E_EXP | E8: ＡＭＡＤＡ ＡＭＥＲＩＣＡ ＩＮＣ． | F8: EGB1303E-E | G8: LZS+BIS+AF | H8: 0D9825 | I8: BDA1298 | J8: 2026/08/26 | K8: 2026/09/11
A9: TS13329993 | B9: 10月 | C9: 007 | D9: EGB1303E | F9: EGB1303E-J | G9: STD | H9: 0F5059 | J9: 2026/08/27 | K9: 2026/09/08
A10: TS82577266 | B10: 10月 | C10: 008 | D10: EGB8025E | E10: だいわ（株） | F10: EGB8025E-J | G10: LZS+BIS | H10: 0E1240 | I10: 194885 | J10: 2026/08/27 | K10: 2026/09/11
A11: TS13377322 | B11: 10月 | C11: 009 | D11: EGB1303E_EXP | E11: ＡＭＡＤＡ ＡＭＥＲＩＣＡ ＩＮＣ． | F11: EGB1303E-E | G11: LZS+BIS+AF | H11: 0D9825 | I11: BDA1299 | J11: 2026/08/27 | K11: 2026/09/11
A12: TS60299201 | B12: 10月 | C12: 010 | D12: EGB6020AE_CE | E12: 【AESA】AMADA ITALIA (IT 299154) | F12: EGB6020AE-C | G12: STD | H12: 0G3964 | I12: BDE0162 | J12: 2026/08/29 | K12: 2026/09/18
A13: TS82577267 | B13: 10月 | C13: 011 | D13: EGB8025E | E13: （株）アマダベンディングＳ部 | F13: EGB8025E-J | G13: LZS+BIS | H13: 0E1240 | J13: 2026/09/01 | K13: 2026/09/15
A14: TS82577270 | B14: 10月 | C14: 012 | D14: EGB8025E | E14: （株）アマダベンディングＳ部 | F14: EGB8025E-J | G14: LZS+BIS | H14: 0E1240 | J14: 2026/09/01 | K14: 2026/09/15
A15: TS13377311 | B15: 10月 | C15: 013 | D15: EGB1303E | E15: （株）アマダベンディングＳ部 | F15: EGB1303E-J | G15: LZS+BIS | H15: 0D9824 | J15: 2026/09/03 | K15: 2026/09/17
A16: TS13377315 | B16: 10月 | C16: 014 | D16: EGB1303E | E16: （株）アマダベンディングＳ部 | F16: EGB1303E-J | G16: LZS+BIS | H16: 0D9824 | J16: 2026/09/03 | K16: 2026/09/17
A17: TS62077154 | B17: 10月 | C17: 015 | D17: EGB6020E_EXP | E17: ＡＭＡＤＡ ＡＭＥＲＩＣＡ ＩＮＣ． | F17: EGB6020E-E | G17: LZS+BIS+AF | H17: 0D7905 | I17: BDA1304 | J17: 2026/09/05 | K17: 2026/09/25
A18: TS13377323 | B18: 10月 | C18: 016 | D18: EGB1303E_EXP | E18: ＡＭＡＤＡ ＡＭＥＲＩＣＡ ＩＮＣ． | F18: EGB1303E-E | G18: LZS+BIS+AF | H18: 0D9825 | I18: BDA1300 | J18: 2026/09/05 | K18: 2026/09/24
A19: TS62077153 | B19: 10月 | C19: 017 | D19: EGB6020E_EXP | E19: ＡＭＡＤＡ ＡＭＥＲＩＣＡ ＩＮＣ． | F19: EGB6020E-E | G19: LZS+BIS+AF | H19: 0D7905 | I19: BDA1303 | J19: 2026/09/08 | K19: 2026/09/26
A20: TS62077155 | B20: 10月 | C20: 018 | D20: EGB6020E_EXP | E20: ＡＭＡＤＡ ＡＭＥＲＩＣＡ ＩＮＣ． | F20: EGB6020E-E | G20: LZS+BIS+AF | H20: 0D7905 | I20: BDA1305 | J20: 2026/09/08 | K20: 2026/09/26
A21: TS82577276 | B21: 10月 | C21: 019 | D21: EGB8025E_EXP | E21: ＡＭＡＤＡ ＡＭＥＲＩＣＡ ＩＮＣ． | F21: EGB8025E-E | G21: LZS+BIS+AF | H21: 0E1858 | I21: BDA1308 | J21: 2026/09/09 | K21: 2026/09/26
A22: TS82577279 | B22: 10月 | C22: 020 | D22: EGB8025E_EXP | E22: ＡＭＡＤＡ ＴＡＩＷＡＮ ＩＮＣ． | F22: EGB8025E-E | G22: LZS+BIS+AF | H22: 0E1858 | I22: TW0508 | J22: 2026/09/09 | K22: 2026/09/26
A23: TS13377327 | B23: 10月 | C23: 021 | D23: EGB1303E_EXP | E23: 【ベトナム】Thu？n Nhat | F23: EGB1303E-E | G23: LZS+BIS+AF | H23: 0D9825 | I23: ASB0890 | J23: 2026/09/12 | K23: 2026/09/30
A24: TS62077156 | B24: 10月 | C24: 022 | D24: EGB6020E_EXP | E24: ＡＭＡＤＡ ＡＭＥＲＩＣＡ ＩＮＣ． | F24: EGB6020E-E | G24: LZS+BIS+AF | H24: 0D7905 | I24: BDA1343 | J24: 2026/09/12 | K24: 2026/10/01
A25: TS13377336 | B25: 10月 | C25: 023 | D25: EGB1303E | E25: （株）新興産業 | F25: EGB1303E-J | G25: LZS+BIS | H25: 0D9824 | I25: 194878 | J25: 2026/09/16 | K25: 2026/10/02
A26: TS60299199 | B26: 10月 | C26: 024 | D26: EGB6020AE | E26: （株）アマダベンディングＳ部 | F26: EGB6020AE-J | G26: STD | H26: 0D7904 | J26: 2026/09/16 | K26: 2026/10/07
A27: TS13377331 | B27: 10月 | C27: 025 | D27: EGB1303E_EXP | E27: 【インド】AEROTYNE INDUSTRY PVT LTD. | F27: EGB1303E-E | G27: LZS+BIS+AF | H27: 0D9825 | I27: BDH0619 | J27: 2026/09/16 | K27: 2026/10/02
A28: TS13377328 | B28: 10月 | C28: 026 | D28: EGB1303E | E28: （株）アマダベンディングＳ部 | F28: EGB1303E-J | G28: LZS+BIS | H28: 0D9824 | J28: 2026/09/17 | K28: 2026/10/03
A29: TS82577283 | B29: 10月 | C29: 027 | D29: EGB8025E_EXP | E29: ＡＭＡＤＡ ＡＭＥＲＩＣＡ ＩＮＣ． | F29: EGB8025E-E | G29: LZS+BIS+AF | H29: 0E1858 | I29: BDA1352 | J29: 2026/09/17 | K29: 2026/10/06
A30: TS60299191 | B30: 10月 | C30: 028 | D30: EGB6020AE_EXP | E30: ＡＭＡＤＡ ＣＡＮＡＤＡ ＬＴＤ． | F30: EGB6020AE-E | G30: STD | H30: 0D8050 | I30: BDA1334 | J30: 2026/09/17 | K30: 2026/10/09
A31: TS60299200 | B31: 10月 | C31: 029 | D31: EGB6020AE | E31: 関東精工（株） | F31: EGB6020AE-J | G31: STD | H31: 0D7904 | I31: 195996 | J31: 2026/09/18 | K31: 2026/10/09
A32: TS13377330 | B32: 10月 | C32: 030 | D32: EGB1303E_EXP | E32: 【タイ】Taiwan Metal Precision(Thailand) | F32: EGB1303E-E | G32: LZS+BIS+AF | H32: 0D9825 | I32: ASB0906 | J32: 2026/09/18 | K32: 2026/10/06
A33: TS13377332 | B33: 10月 | C33: 031 | D33: EGB1303E_EXP | E33: ＡＭＡＤＡ ＣＡＮＡＤＡ ＬＴＤ． | F33: EGB1303E-E | G33: LZS+BIS+AF | H33: 0D9825 | I33: BDA1332 | J33: 2026/09/18 | K33: 2026/10/06
A34: TS13399260 | B34: 10月 | C34: 032 | D34: EGB1303AE | E34: （株）アマダベンディングＳ部 | F34: EGB1303AE-J | G34: STD | H34: 0D9621 | J34: 2026/09/19 | K34: 2026/10/10
A35: TS82577288 | B35: 10月 | C35: 033 | D35: EGB8025E | E35: フクシマガリレイ（株） | F35: EGB8025E-J | G35: LZS+BIS | H35: 0E1240 | I35: 194881 | J35: 2026/09/19 | K35: 2026/10/07
A36: TS62077157 | B36: 10月 | C36: 034 | D36: EGB6020E_EXP | E36: ＡＭＡＤＡ ＣＡＮＡＤＡ ＬＴＤ． | F36: EGB6020E-E | G36: LZS+BIS+AF | H36: 0D7905 | I36: BDA1347 | J36: 2026/09/19 | K36: 2026/10/08
A37: TS13377326 | B37: 10月 | C37: 035 | D37: EGB1303E | E37: 文化シヤッター（株） | F37: EGB1303E-J | G37: LZS+BIS | H37: 0D9824 | I37: 193755 | J37: 2026/09/24 | K37: 2026/10/07
A38: TS13399257 | B38: 10月 | C38: 036 | D38: EGB1303AE_EXP | E38: ＡＭＡＤＡ ＣＡＮＡＤＡ ＬＴＤ． | F38: EGB1303AE-E | G38: STD | H38: 0E1243 | I38: BDA1326 | J38: 2026/09/24 | K38: 2026/10/13
A39: TS82577284 | B39: 10月 | C39: 037 | D39: EGB8025E_EXP | E39: 【ベトナム】Department of Metrology & St | F39: EGB8025E-E | G39: LZS+BIS+AF | H39: 0E1858 | I39: ASB0901 | J39: 2026/09/24 | K39: 2026/10/08
A40: TS13377337 | B40: 10月 | C40: 038 | D40: EGB1303E | E40: アートテックス（株） | F40: EGB1303E-J | G40: LZS+BIS | H40: 0D9824 | I40: 194877 | J40: 2026/09/25 | K40: 2026/10/08
A41: TS62077160 | B41: 10月 | C41: 039 | D41: EGB6020E | E41: （株）広島メタルワーク | F41: EGB6020E-J | G41: LZS+BIS | H41: 0D7255 | I41: 195950 | J41: 2026/09/26 | K41: 2026/10/10
...

Sheet ﾍﾞﾝﾀﾞｰ小型対照表
A1: NO | B1: 生産月 | C1: 機種名 | D1: 客先名 | E1: シリアルNo | F1: 機種品番 | G1: 着手日(変更前) | I1: 着手日(変更後)
A2: 1 | B2: =IFERROR(VLOOKUP(E2,'(新)ﾍﾞﾝﾀﾞｰ小型'!$A$3:$K$300,2,0), "") -> 10月 | C2: =IFERROR(VLOOKUP(E2,'(新)ﾍﾞﾝﾀﾞｰ小型'!$A$3:$K$300,4,0), "") -> EGB1303ARE_EXP | D2: =IFERROR(VLOOKUP(E2,'(新)ﾍﾞﾝﾀﾞｰ小型'!$A$3:$K$300,5,0), "") -> ＡＭＡＤＡ ＡＭＥＲＩＣＡ ＩＮＣ． | E2: ='(新)ﾍﾞﾝﾀﾞｰ小型'!A3 -> TS13329056 | F2: =IFERROR(VLOOKUP(E2,'(新)ﾍﾞﾝﾀﾞｰ小型'!$A$3:$K$300,8,0), "") -> 0E1859 | G2: =IFERROR(VLOOKUP(E2,'(旧)ﾍﾞﾝﾀﾞｰ小型'!$A$3:$K$310,10,0),"") -> 2026/08/01 | H2: ⇒ | I2: =IFERROR(VLOOKUP(E2,'(新)ﾍﾞﾝﾀﾞｰ小型'!$A$3:$K$300,10,0),"") -> 2026/08/01
A3: 2 | B3: =IFERROR(VLOOKUP(E3,'(新)ﾍﾞﾝﾀﾞｰ小型'!$A$3:$K$300,2,0), "") -> 10月 | C3: =IFERROR(VLOOKUP(E3,'(新)ﾍﾞﾝﾀﾞｰ小型'!$A$3:$K$300,4,0), "") -> EGB1303AE_EXP | D3: =IFERROR(VLOOKUP(E3,'(新)ﾍﾞﾝﾀﾞｰ小型'!$A$3:$K$300,5,0), "") -> Ａｍａｄａ Ｏｃｅａｎｉａ Ｐｔｙ Ｌｔ | E3: ='(新)ﾍﾞﾝﾀﾞｰ小型'!A4 -> TS13399252 | F3: =IFERROR(VLOOKUP(E3,'(新)ﾍﾞﾝﾀﾞｰ小型'!$A$3:$K$300,8,0), "") -> 0E1243 | G3: =IFERROR(VLOOKUP(E3,'(旧)ﾍﾞﾝﾀﾞｰ小型'!$A$3:$K$310,10,0),"") -> 2026/08/05 | H3: ⇒ | I3: =IFERROR(VLOOKUP(E3,'(新)ﾍﾞﾝﾀﾞｰ小型'!$A$3:$K$300,10,0),"") -> 2026/08/05
A4: 3 | B4: =IFERROR(VLOOKUP(E4,'(新)ﾍﾞﾝﾀﾞｰ小型'!$A$3:$K$300,2,0), "") -> 10月 | C4: =IFERROR(VLOOKUP(E4,'(新)ﾍﾞﾝﾀﾞｰ小型'!$A$3:$K$300,4,0), "") -> EGB1303AE | D4: =IFERROR(VLOOKUP(E4,'(新)ﾍﾞﾝﾀﾞｰ小型'!$A$3:$K$300,5,0), "") -> （株）アマダベンディングＳ部 | E4: ='(新)ﾍﾞﾝﾀﾞｰ小型'!A5 -> TS13399248 | F4: =IFERROR(VLOOKUP(E4,'(新)ﾍﾞﾝﾀﾞｰ小型'!$A$3:$K$300,8,0), "") -> 0D9621 | G4: =IFERROR(VLOOKUP(E4,'(旧)ﾍﾞﾝﾀﾞｰ小型'!$A$3:$K$310,10,0),"") -> 2026/08/08 | H4: ⇒ | I4: =IFERROR(VLOOKUP(E4,'(新)ﾍﾞﾝﾀﾞｰ小型'!$A$3:$K$300,10,0),"") -> 2026/08/08
A5: 4 | B5: =IFERROR(VLOOKUP(E5,'(新)ﾍﾞﾝﾀﾞｰ小型'!$A$3:$K$300,2,0), "") -> 10月 | C5: =IFERROR(VLOOKUP(E5,'(新)ﾍﾞﾝﾀﾞｰ小型'!$A$3:$K$300,4,0), "") -> EGB6020AE_EXP | D5: =IFERROR(VLOOKUP(E5,'(新)ﾍﾞﾝﾀﾞｰ小型'!$A$3:$K$300,5,0), "") -> ＡＭＡＤＡ ＴＡＩＷＡＮ ＩＮＣ． | E5: ='(新)ﾍﾞﾝﾀﾞｰ小型'!A6 -> TS60299196 | F5: =IFERROR(VLOOKUP(E5,'(新)ﾍﾞﾝﾀﾞｰ小型'!$A$3:$K$300,8,0), "") -> 0D8050 | G5: =IFERROR(VLOOKUP(E5,'(旧)ﾍﾞﾝﾀﾞｰ小型'!$A$3:$K$310,10,0),"") -> 2026/08/19 | H5: ⇒ | I5: =IFERROR(VLOOKUP(E5,'(新)ﾍﾞﾝﾀﾞｰ小型'!$A$3:$K$300,10,0),"") -> 2026/08/19
A6: 5 | B6: =IFERROR(VLOOKUP(E6,'(新)ﾍﾞﾝﾀﾞｰ小型'!$A$3:$K$300,2,0), "") -> 10月 | C6: =IFERROR(VLOOKUP(E6,'(新)ﾍﾞﾝﾀﾞｰ小型'!$A$3:$K$300,4,0), "") -> EGB1303E | D6: =IFERROR(VLOOKUP(E6,'(新)ﾍﾞﾝﾀﾞｰ小型'!$A$3:$K$300,5,0), "") -> （株）アマダベンディングＳ部 | E6: ='(新)ﾍﾞﾝﾀﾞｰ小型'!A7 -> TS13377312 | F6: =IFERROR(VLOOKUP(E6,'(新)ﾍﾞﾝﾀﾞｰ小型'!$A$3:$K$300,8,0), "") -> 0D9824 | G6: =IFERROR(VLOOKUP(E6,'(旧)ﾍﾞﾝﾀﾞｰ小型'!$A$3:$K$310,10,0),"") -> 2026/08/26 | H6: ⇒ | I6: =IFERROR(VLOOKUP(E6,'(新)ﾍﾞﾝﾀﾞｰ小型'!$A$3:$K$300,10,0),"") -> 2026/08/26
A7: 6 | B7: =IFERROR(VLOOKUP(E7,'(新)ﾍﾞﾝﾀﾞｰ小型'!$A$3:$K$300,2,0), "") -> 10月 | C7: =IFERROR(VLOOKUP(E7,'(新)ﾍﾞﾝﾀﾞｰ小型'!$A$3:$K$300,4,0), "") -> EGB1303E_EXP | D7: =IFERROR(VLOOKUP(E7,'(新)ﾍﾞﾝﾀﾞｰ小型'!$A$3:$K$300,5,0), "") -> ＡＭＡＤＡ ＡＭＥＲＩＣＡ ＩＮＣ． | E7: ='(新)ﾍﾞﾝﾀﾞｰ小型'!A8 -> TS13377321 | F7: =IFERROR(VLOOKUP(E7,'(新)ﾍﾞﾝﾀﾞｰ小型'!$A$3:$K$300,8,0), "") -> 0D9825 | G7: =IFERROR(VLOOKUP(E7,'(旧)ﾍﾞﾝﾀﾞｰ小型'!$A$3:$K$310,10,0),"") -> 2026/08/26 | H7: ⇒ | I7: =IFERROR(VLOOKUP(E7,'(新)ﾍﾞﾝﾀﾞｰ小型'!$A$3:$K$300,10,0),"") -> 2026/08/26
A8: 7 | B8: =IFERROR(VLOOKUP(E8,'(新)ﾍﾞﾝﾀﾞｰ小型'!$A$3:$K$300,2,0), "") -> 10月 | C8: =IFERROR(VLOOKUP(E8,'(新)ﾍﾞﾝﾀﾞｰ小型'!$A$3:$K$300,4,0), "") -> EGB1303E | D8: =IFERROR(VLOOKUP(E8,'(新)ﾍﾞﾝﾀﾞｰ小型'!$A$3:$K$300,5,0), "") | E8: ='(新)ﾍﾞﾝﾀﾞｰ小型'!A9 -> TS13329993 | F8: =IFERROR(VLOOKUP(E8,'(新)ﾍﾞﾝﾀﾞｰ小型'!$A$3:$K$300,8,0), "") -> 0F5059 | G8: =IFERROR(VLOOKUP(E8,'(旧)ﾍﾞﾝﾀﾞｰ小型'!$A$3:$K$310,10,0),"") -> 2026/08/27 | H8: ⇒ | I8: =IFERROR(VLOOKUP(E8,'(新)ﾍﾞﾝﾀﾞｰ小型'!$A$3:$K$300,10,0),"") -> 2026/08/27
A9: 8 | B9: =IFERROR(VLOOKUP(E9,'(新)ﾍﾞﾝﾀﾞｰ小型'!$A$3:$K$300,2,0), "") -> 10月 | C9: =IFERROR(VLOOKUP(E9,'(新)ﾍﾞﾝﾀﾞｰ小型'!$A$3:$K$300,4,0), "") -> EGB8025E | D9: =IFERROR(VLOOKUP(E9,'(新)ﾍﾞﾝﾀﾞｰ小型'!$A$3:$K$300,5,0), "") -> だいわ（株） | E9: ='(新)ﾍﾞﾝﾀﾞｰ小型'!A10 -> TS82577266 | F9: =IFERROR(VLOOKUP(E9,'(新)ﾍﾞﾝﾀﾞｰ小型'!$A$3:$K$300,8,0), "") -> 0E1240 | G9: =IFERROR(VLOOKUP(E9,'(旧)ﾍﾞﾝﾀﾞｰ小型'!$A$3:$K$310,10,0),"") -> 2026/08/27 | H9: ⇒ | I9: =IFERROR(VLOOKUP(E9,'(新)ﾍﾞﾝﾀﾞｰ小型'!$A$3:$K$300,10,0),"") -> 2026/08/27
A10: 9 | B10: =IFERROR(VLOOKUP(E10,'(新)ﾍﾞﾝﾀﾞｰ小型'!$A$3:$K$300,2,0), "") -> 10月 | C10: =IFERROR(VLOOKUP(E10,'(新)ﾍﾞﾝﾀﾞｰ小型'!$A$3:$K$300,4,0), "") -> EGB1303E_EXP | D10: =IFERROR(VLOOKUP(E10,'(新)ﾍﾞﾝﾀﾞｰ小型'!$A$3:$K$300,5,0), "") -> ＡＭＡＤＡ ＡＭＥＲＩＣＡ ＩＮＣ． | E10: ='(新)ﾍﾞﾝﾀﾞｰ小型'!A11 -> TS13377322 | F10: =IFERROR(VLOOKUP(E10,'(新)ﾍﾞﾝﾀﾞｰ小型'!$A$3:$K$300,8,0), "") -> 0D9825 | G10: =IFERROR(VLOOKUP(E10,'(旧)ﾍﾞﾝﾀﾞｰ小型'!$A$3:$K$310,10,0),"") -> 2026/08/27 | H10: ⇒ | I10: =IFERROR(VLOOKUP(E10,'(新)ﾍﾞﾝﾀﾞｰ小型'!$A$3:$K$300,10,0),"") -> 2026/08/27
A11: 10 | B11: =IFERROR(VLOOKUP(E11,'(新)ﾍﾞﾝﾀﾞｰ小型'!$A$3:$K$300,2,0), "") -> 10月 | C11: =IFERROR(VLOOKUP(E11,'(新)ﾍﾞﾝﾀﾞｰ小型'!$A$3:$K$300,4,0), "") -> EGB6020AE_CE | D11: =IFERROR(VLOOKUP(E11,'(新)ﾍﾞﾝﾀﾞｰ小型'!$A$3:$K$300,5,0), "") -> 【AESA】AMADA ITALIA (IT 299154) | E11: ='(新)ﾍﾞﾝﾀﾞｰ小型'!A12 -> TS60299201 | F11: =IFERROR(VLOOKUP(E11,'(新)ﾍﾞﾝﾀﾞｰ小型'!$A$3:$K$300,8,0), "") -> 0G3964 | G11: =IFERROR(VLOOKUP(E11,'(旧)ﾍﾞﾝﾀﾞｰ小型'!$A$3:$K$310,10,0),"") -> 2026/08/29 | H11: ⇒ | I11: =IFERROR(VLOOKUP(E11,'(新)ﾍﾞﾝﾀﾞｰ小型'!$A$3:$K$300,10,0),"") -> 2026/08/29
A12: 11 | B12: =IFERROR(VLOOKUP(E12,'(新)ﾍﾞﾝﾀﾞｰ小型'!$A$3:$K$300,2,0), "") -> 10月 | C12: =IFERROR(VLOOKUP(E12,'(新)ﾍﾞﾝﾀﾞｰ小型'!$A$3:$K$300,4,0), "") -> EGB8025E | D12: =IFERROR(VLOOKUP(E12,'(新)ﾍﾞﾝﾀﾞｰ小型'!$A$3:$K$300,5,0), "") -> （株）アマダベンディングＳ部 | E12: ='(新)ﾍﾞﾝﾀﾞｰ小型'!A13 -> TS82577267 | F12: =IFERROR(VLOOKUP(E12,'(新)ﾍﾞﾝﾀﾞｰ小型'!$A$3:$K$300,8,0), "") -> 0E1240 | G12: =IFERROR(VLOOKUP(E12,'(旧)ﾍﾞﾝﾀﾞｰ小型'!$A$3:$K$310,10,0),"") -> 2026/09/01 | H12: ⇒ | I12: =IFERROR(VLOOKUP(E12,'(新)ﾍﾞﾝﾀﾞｰ小型'!$A$3:$K$300,10,0),"") -> 2026/09/01
A13: 12 | B13: =IFERROR(VLOOKUP(E13,'(新)ﾍﾞﾝﾀﾞｰ小型'!$A$3:$K$300,2,0), "") -> 10月 | C13: =IFERROR(VLOOKUP(E13,'(新)ﾍﾞﾝﾀﾞｰ小型'!$A$3:$K$300,4,0), "") -> EGB8025E | D13: =IFERROR(VLOOKUP(E13,'(新)ﾍﾞﾝﾀﾞｰ小型'!$A$3:$K$300,5,0), "") -> （株）アマダベンディングＳ部 | E13: ='(新)ﾍﾞﾝﾀﾞｰ小型'!A14 -> TS82577270 | F13: =IFERROR(VLOOKUP(E13,'(新)ﾍﾞﾝﾀﾞｰ小型'!$A$3:$K$300,8,0), "") -> 0E1240 | G13: =IFERROR(VLOOKUP(E13,'(旧)ﾍﾞﾝﾀﾞｰ小型'!$A$3:$K$310,10,0),"") -> 2026/09/01 | H13: ⇒ | I13: =IFERROR(VLOOKUP(E13,'(新)ﾍﾞﾝﾀﾞｰ小型'!$A$3:$K$300,10,0),"") -> 2026/09/01
... A285: 284 | B285: =IFERROR(VLOOKUP(E285,'(新)ﾍﾞﾝﾀﾞｰ小型'!$A$3:$K$300,2,0), "") -> 03月 | C285: =IFERROR(VLOOKUP(E285,'(新)ﾍﾞﾝﾀﾞｰ小型'!$A$3:$K$300,4,0), "") -> EGB1303E_EXP | D285: =IFERROR(VLOOKUP(E285,'(新)ﾍﾞﾝﾀﾞｰ小型'!$A$3:$K$300,5,0), "") -> アマダアメリカ | E285: ='(新)ﾍﾞﾝﾀﾞｰ小型'!A286 -> TS13377381 | F285: =IFERROR(VLOOKUP(E285,'(新)ﾍﾞﾝﾀﾞｰ小型'!$A$3:$K$300,8,0), "") -> 0D9825 | G285: =IFERROR(VLOOKUP(E285,'(旧)ﾍﾞﾝﾀﾞｰ小型'!$A$3:$K$310,10,0),"") | H285: ⇒ | I285: =IFERROR(VLOOKUP(E285,'(新)ﾍﾞﾝﾀﾞｰ小型'!$A$3:$K$300,10,0),"") -> 2027/03/02
A286: 285 | B286: =IFERROR(VLOOKUP(E286,'(新)ﾍﾞﾝﾀﾞｰ小型'!$A$3:$K$300,2,0), "") -> 03月 | C286: =IFERROR(VLOOKUP(E286,'(新)ﾍﾞﾝﾀﾞｰ小型'!$A$3:$K$300,4,0), "") -> EGB1303E_EXP | D286: =IFERROR(VLOOKUP(E286,'(新)ﾍﾞﾝﾀﾞｰ小型'!$A$3:$K$241,5,0), "") | E286: ='(新)ﾍﾞﾝﾀﾞｰ小型'!A287 -> TS13377382 | F286: =IFERROR(VLOOKUP(E286,'(新)ﾍﾞﾝﾀﾞｰ小型'!$A$3:$K$300,8,0), "") -> 0D9825 | G286: =IFERROR(VLOOKUP(E286,'(旧)ﾍﾞﾝﾀﾞｰ小型'!$A$3:$K$310,10,0),"") | H286: ⇒ | I286: =IFERROR(VLOOKUP(E286,'(新)ﾍﾞﾝﾀﾞｰ小型'!$A$3:$K$300,10,0),"") -> 2027/03/03
A287: 286 | B287: =IFERROR(VLOOKUP(E287,'(新)ﾍﾞﾝﾀﾞｰ小型'!$A$3:$K$300,2,0), "") -> 03月 | C287: =IFERROR(VLOOKUP(E287,'(新)ﾍﾞﾝﾀﾞｰ小型'!$A$3:$K$300,4,0), "") -> EGB8025E_EXP | D287: =IFERROR(VLOOKUP(E287,'(新)ﾍﾞﾝﾀﾞｰ小型'!$A$3:$K$241,5,0), "") | E287: ='(新)ﾍﾞﾝﾀﾞｰ小型'!A288 -> TS82577334 | F287: =IFERROR(VLOOKUP(E287,'(新)ﾍﾞﾝﾀﾞｰ小型'!$A$3:$K$300,8,0), "") -> 0E1858 | G287: =IFERROR(VLOOKUP(E287,'(旧)ﾍﾞﾝﾀﾞｰ小型'!$A$3:$K$310,10,0),"") | H287: ⇒ | I287: =IFERROR(VLOOKUP(E287,'(新)ﾍﾞﾝﾀﾞｰ小型'!$A$3:$K$300,10,0),"") -> 2027/03/03
A288: 287 | B288: =IFERROR(VLOOKUP(E288,'(新)ﾍﾞﾝﾀﾞｰ小型'!$A$3:$K$300,2,0), "") -> 03月 | C288: =IFERROR(VLOOKUP(E288,'(新)ﾍﾞﾝﾀﾞｰ小型'!$A$3:$K$300,4,0), "") -> EGB8025E_EXP | D288: =IFERROR(VLOOKUP(E288,'(新)ﾍﾞﾝﾀﾞｰ小型'!$A$3:$K$241,5,0), "") | E288: ='(新)ﾍﾞﾝﾀﾞｰ小型'!A289 -> TS82577335 | F288: =IFERROR(VLOOKUP(E288,'(新)ﾍﾞﾝﾀﾞｰ小型'!$A$3:$K$300,8,0), "") -> 0E1858 | G288: =IFERROR(VLOOKUP(E288,'(旧)ﾍﾞﾝﾀﾞｰ小型'!$A$3:$K$310,10,0),"") | H288: ⇒ | I288: =IFERROR(VLOOKUP(E288,'(新)ﾍﾞﾝﾀﾞｰ小型'!$A$3:$K$300,10,0),"") -> 2027/03/04
A289: 288 | B289: =IFERROR(VLOOKUP(E289,'(新)ﾍﾞﾝﾀﾞｰ小型'!$A$3:$K$300,2,0), "") -> 03月 | C289: =IFERROR(VLOOKUP(E289,'(新)ﾍﾞﾝﾀﾞｰ小型'!$A$3:$K$300,4,0), "") -> EGB8025E_EXP | D289: =IFERROR(VLOOKUP(E289,'(新)ﾍﾞﾝﾀﾞｰ小型'!$A$3:$K$241,5,0), "") | E289: ='(新)ﾍﾞﾝﾀﾞｰ小型'!A290 -> TS82577336 | F289: =IFERROR(VLOOKUP(E289,'(新)ﾍﾞﾝﾀﾞｰ小型'!$A$3:$K$300,8,0), "") -> 0E1858 | G289: =IFERROR(VLOOKUP(E289,'(旧)ﾍﾞﾝﾀﾞｰ小型'!$A$3:$K$310,10,0),"") | H289: ⇒ | I289: =IFERROR(VLOOKUP(E289,'(新)ﾍﾞﾝﾀﾞｰ小型'!$A$3:$K$300,10,0),"") -> 2027/03/04
A290: 289 | B290: =IFERROR(VLOOKUP(E290,'(新)ﾍﾞﾝﾀﾞｰ小型'!$A$3:$K$300,2,0), "") -> 03月 | C290: =IFERROR(VLOOKUP(E290,'(新)ﾍﾞﾝﾀﾞｰ小型'!$A$3:$K$300,4,0), "") -> EGB1303E_EXP | D290: =IFERROR(VLOOKUP(E290,'(新)ﾍﾞﾝﾀﾞｰ小型'!$A$3:$K$241,5,0), "") | E290: ='(新)ﾍﾞﾝﾀﾞｰ小型'!A291 -> TS13377384 | F290: =IFERROR(VLOOKUP(E290,'(新)ﾍﾞﾝﾀﾞｰ小型'!$A$3:$K$300,8,0), "") -> 0D9825 | G290: =IFERROR(VLOOKUP(E290,'(旧)ﾍﾞﾝﾀﾞｰ小型'!$A$3:$K$310,10,0),"") | H290: ⇒ | I290: =IFERROR(VLOOKUP(E290,'(新)ﾍﾞﾝﾀﾞｰ小型'!$A$3:$K$300,10,0),"") -> 2027/03/05
A291: 290 | B291: =IFERROR(VLOOKUP(E291,'(新)ﾍﾞﾝﾀﾞｰ小型'!$A$3:$K$300,2,0), "") -> 03月 | C291: =IFERROR(VLOOKUP(E291,'(新)ﾍﾞﾝﾀﾞｰ小型'!$A$3:$K$300,4,0), "") -> EGB1303E_EXP | D291: =IFERROR(VLOOKUP(E291,'(新)ﾍﾞﾝﾀﾞｰ小型'!$A$3:$K$241,5,0), "") | E291: ='(新)ﾍﾞﾝﾀﾞｰ小型'!A292 -> TS13377383 | F291: =IFERROR(VLOOKUP(E291,'(新)ﾍﾞﾝﾀﾞｰ小型'!$A$3:$K$300,8,0), "") -> 0D9825 | G291: =IFERROR(VLOOKUP(E291,'(旧)ﾍﾞﾝﾀﾞｰ小型'!$A$3:$K$310,10,0),"") | H291: ⇒ | I291: =IFERROR(VLOOKUP(E291,'(新)ﾍﾞﾝﾀﾞｰ小型'!$A$3:$K$300,10,0),"") -> 2027/03/06
A292: 291 | B292: =IFERROR(VLOOKUP(E292,'(新)ﾍﾞﾝﾀﾞｰ小型'!$A$3:$K$300,2,0), "") -> 03月 | C292: =IFERROR(VLOOKUP(E292,'(新)ﾍﾞﾝﾀﾞｰ小型'!$A$3:$K$300,4,0), "") -> EGB1303E_EXP | D292: =IFERROR(VLOOKUP(E292,'(新)ﾍﾞﾝﾀﾞｰ小型'!$A$3:$K$241,5,0), "") | E292: ='(新)ﾍﾞﾝﾀﾞｰ小型'!A293 -> TS13377385 | F292: =IFERROR(VLOOKUP(E292,'(新)ﾍﾞﾝﾀﾞｰ小型'!$A$3:$K$300,8,0), "") -> 0D9825 | G292: =IFERROR(VLOOKUP(E292,'(旧)ﾍﾞﾝﾀﾞｰ小型'!$A$3:$K$310,10,0),"") | H292: ⇒ | I292: =IFERROR(VLOOKUP(E292,'(新)ﾍﾞﾝﾀﾞｰ小型'!$A$3:$K$300,10,0),"") -> 2027/03/06
A293: 292 | B293: =IFERROR(VLOOKUP(E293,'(新)ﾍﾞﾝﾀﾞｰ小型'!$A$3:$K$300,2,0), "") -> 03月 | C293: =IFERROR(VLOOKUP(E293,'(新)ﾍﾞﾝﾀﾞｰ小型'!$A$3:$K$300,4,0), "") -> EGB8025E_EXP | D293: =IFERROR(VLOOKUP(E293,'(新)ﾍﾞﾝﾀﾞｰ小型'!$A$3:$K$241,5,0), "") | E293: ='(新)ﾍﾞﾝﾀﾞｰ小型'!A294 -> TS82577337 | F293: =IFERROR(VLOOKUP(E293,'(新)ﾍﾞﾝﾀﾞｰ小型'!$A$3:$K$300,8,0), "") -> 0E1858 | G293: =IFERROR(VLOOKUP(E293,'(旧)ﾍﾞﾝﾀﾞｰ小型'!$A$3:$K$310,10,0),"") | H293: ⇒ | I293: =IFERROR(VLOOKUP(E293,'(新)ﾍﾞﾝﾀﾞｰ小型'!$A$3:$K$300,10,0),"") -> 2027/03/09
A294: 293 | B294: =IFERROR(VLOOKUP(E294,'(新)ﾍﾞﾝﾀﾞｰ小型'!$A$3:$K$300,2,0), "") -> 03月 | C294: =IFERROR(VLOOKUP(E294,'(新)ﾍﾞﾝﾀﾞｰ小型'!$A$3:$K$300,4,0), "") -> EGB8025E | D294: =IFERROR(VLOOKUP(E294,'(新)ﾍﾞﾝﾀﾞｰ小型'!$A$3:$K$241,5,0), "") | E294: ='(新)ﾍﾞﾝﾀﾞｰ小型'!A295 -> TS82577328 | F294: =IFERROR(VLOOKUP(E294,'(新)ﾍﾞﾝﾀﾞｰ小型'!$A$3:$K$300,8,0), "") -> 0E1240 | G294: =IFERROR(VLOOKUP(E294,'(旧)ﾍﾞﾝﾀﾞｰ小型'!$A$3:$K$310,10,0),"") | H294: ⇒ | I294: =IFERROR(VLOOKUP(E294,'(新)ﾍﾞﾝﾀﾞｰ小型'!$A$3:$K$300,10,0),"") -> 2027/03/09
A295: 294 | B295: =IFERROR(VLOOKUP(E295,'(新)ﾍﾞﾝﾀﾞｰ小型'!$A$3:$K$300,2,0), "") -> 03月 | C295: =IFERROR(VLOOKUP(E295,'(新)ﾍﾞﾝﾀﾞｰ小型'!$A$3:$K$300,4,0), "") -> EGB6020E | D295: =IFERROR(VLOOKUP(E295,'(新)ﾍﾞﾝﾀﾞｰ小型'!$A$3:$K$241,5,0), "") | E295: ='(新)ﾍﾞﾝﾀﾞｰ小型'!A296 -> TS62077196 | F295: =IFERROR(VLOOKUP(E295,'(新)ﾍﾞﾝﾀﾞｰ小型'!$A$3:$K$300,8,0), "") -> 0D7255 | G295: =IFERROR(VLOOKUP(E295,'(旧)ﾍﾞﾝﾀﾞｰ小型'!$A$3:$K$310,10,0),"") | H295: ⇒ | I295: =IFERROR(VLOOKUP(E295,'(新)ﾍﾞﾝﾀﾞｰ小型'!$A$3:$K$300,10,0),"") -> 2027/03/10
A296: 295 | B296: =IFERROR(VLOOKUP(E296,'(新)ﾍﾞﾝﾀﾞｰ小型'!$A$3:$K$300,2,0), "") -> 03月 | C296: =IFERROR(VLOOKUP(E296,'(新)ﾍﾞﾝﾀﾞｰ小型'!$A$3:$K$300,4,0), "") -> EGB6020E | D296: =IFERROR(VLOOKUP(E296,'(新)ﾍﾞﾝﾀﾞｰ小型'!$A$3:$K$241,5,0), "") | E296: ='(新)ﾍﾞﾝﾀﾞｰ小型'!A297 -> TS62077197 | F296: =IFERROR(VLOOKUP(E296,'(新)ﾍﾞﾝﾀﾞｰ小型'!$A$3:$K$300,8,0), "") -> 0D7255 | G296: =IFERROR(VLOOKUP(E296,'(旧)ﾍﾞﾝﾀﾞｰ小型'!$A$3:$K$310,10,0),"") | H296: ⇒ | I296: =IFERROR(VLOOKUP(E296,'(新)ﾍﾞﾝﾀﾞｰ小型'!$A$3:$K$300,10,0),"") -> 2027/03/11
A297: 296 | B297: =IFERROR(VLOOKUP(E297,'(新)ﾍﾞﾝﾀﾞｰ小型'!$A$3:$K$300,2,0), "") -> 03月 | C297: =IFERROR(VLOOKUP(E297,'(新)ﾍﾞﾝﾀﾞｰ小型'!$A$3:$K$300,4,0), "") -> EGB6020E | D297: =IFERROR(VLOOKUP(E297,'(新)ﾍﾞﾝﾀﾞｰ小型'!$A$3:$K$241,5,0), "") | E297: ='(新)ﾍﾞﾝﾀﾞｰ小型'!A298 -> TS62077203 | F297: =IFERROR(VLOOKUP(E297,'(新)ﾍﾞﾝﾀﾞｰ小型'!$A$3:$K$300,8,0), "") -> 0D7255 | G297: =IFERROR(VLOOKUP(E297,'(旧)ﾍﾞﾝﾀﾞｰ小型'!$A$3:$K$310,10,0),"") | H297: ⇒ | I297: =IFERROR(VLOOKUP(E297,'(新)ﾍﾞﾝﾀﾞｰ小型'!$A$3:$K$300,10,0),"") -> 2027/03/11
... A301: 300 | B301: =IFERROR(VLOOKUP(E301,'(新)ﾍﾞﾝﾀﾞｰ小型'!$A$3:$K$300,2,0), "") | C301: =IFERROR(VLOOKUP(E301,'(新)ﾍﾞﾝﾀﾞｰ小型'!$A$3:$K$300,4,0), "") | D301: =IFERROR(VLOOKUP(E301,'(新)ﾍﾞﾝﾀﾞｰ小型'!$A$3:$K$241,5,0), "") | E301: ='(新)ﾍﾞﾝﾀﾞｰ小型'!A302 -> TS82577330 | F301: =IFERROR(VLOOKUP(E301,'(新)ﾍﾞﾝﾀﾞｰ小型'!$A$3:$K$300,8,0), "") | G301: =IFERROR(VLOOKUP(E301,'(旧)ﾍﾞﾝﾀﾞｰ小型'!$A$3:$K$310,10,0),"") | H301: ⇒ | I301: =IFERROR(VLOOKUP(E301,'(新)ﾍﾞﾝﾀﾞｰ小型'!$A$3:$K$300,10,0),"")
A302: 301 | B302: =IFERROR(VLOOKUP(E302,'(新)ﾍﾞﾝﾀﾞｰ小型'!$A$3:$K$241,2,0), "") | C302: =IFERROR(VLOOKUP(E302,'(新)ﾍﾞﾝﾀﾞｰ小型'!$A$3:$K$300,4,0), "") | D302: =IFERROR(VLOOKUP(E302,'(新)ﾍﾞﾝﾀﾞｰ小型'!$A$3:$K$241,5,0), "") | E302: ='(新)ﾍﾞﾝﾀﾞｰ小型'!A303 -> TS82577331 | F302: =IFERROR(VLOOKUP(E302,'(新)ﾍﾞﾝﾀﾞｰ小型'!$A$3:$K$300,8,0), "") | G302: =IFERROR(VLOOKUP(E302,'(旧)ﾍﾞﾝﾀﾞｰ小型'!$A$3:$K$310,10,0),"") | H302: ⇒ | I302: =IFERROR(VLOOKUP(E302,'(新)ﾍﾞﾝﾀﾞｰ小型'!$A$3:$K$300,10,0),"")
A303: 302 | B303: =IFERROR(VLOOKUP(E303,'(新)ﾍﾞﾝﾀﾞｰ小型'!$A$3:$K$241,2,0), "") | C303: =IFERROR(VLOOKUP(E303,'(新)ﾍﾞﾝﾀﾞｰ小型'!$A$3:$K$300,4,0), "") | D303: =IFERROR(VLOOKUP(E303,'(新)ﾍﾞﾝﾀﾞｰ小型'!$A$3:$K$241,5,0), "") | E303: ='(新)ﾍﾞﾝﾀﾞｰ小型'!A304 -> TS82577333 | F303: =IFERROR(VLOOKUP(E303,'(新)ﾍﾞﾝﾀﾞｰ小型'!$A$3:$K$300,8,0), "") | G303: =IFERROR(VLOOKUP(E303,'(旧)ﾍﾞﾝﾀﾞｰ小型'!$A$3:$K$310,10,0),"") | H303: ⇒ | I303: =IFERROR(VLOOKUP(E303,'(新)ﾍﾞﾝﾀﾞｰ小型'!$A$3:$K$300,10,0),"")
A304: 303 | B304: =IFERROR(VLOOKUP(E304,'(新)ﾍﾞﾝﾀﾞｰ小型'!$A$3:$K$241,2,0), "") | C304: =IFERROR(VLOOKUP(E304,'(新)ﾍﾞﾝﾀﾞｰ小型'!$A$3:$K$300,4,0), "") | D304: =IFERROR(VLOOKUP(E304,'(新)ﾍﾞﾝﾀﾞｰ小型'!$A$3:$K$241,5,0), "") | E304: ='(新)ﾍﾞﾝﾀﾞｰ小型'!A305 -> TS82577332 | F304: =IFERROR(VLOOKUP(E304,'(新)ﾍﾞﾝﾀﾞｰ小型'!$A$3:$K$300,8,0), "") | G304: =IFERROR(VLOOKUP(E304,'(旧)ﾍﾞﾝﾀﾞｰ小型'!$A$3:$K$310,10,0),"") | H304: ⇒ | I304: =IFERROR(VLOOKUP(E304,'(新)ﾍﾞﾝﾀﾞｰ小型'!$A$3:$K$300,10,0),"")
A305: 304 | B305: =IFERROR(VLOOKUP(E305,'(新)ﾍﾞﾝﾀﾞｰ小型'!$A$3:$K$241,2,0), "") | C305: =IFERROR(VLOOKUP(E305,'(新)ﾍﾞﾝﾀﾞｰ小型'!$A$3:$K$300,4,0), "") | D305: =IFERROR(VLOOKUP(E305,'(新)ﾍﾞﾝﾀﾞｰ小型'!$A$3:$K$241,5,0), "") | E305: ='(新)ﾍﾞﾝﾀﾞｰ小型'!A306 -> TS82577342 | F305: =IFERROR(VLOOKUP(E305,'(新)ﾍﾞﾝﾀﾞｰ小型'!$A$3:$K$300,8,0), "") | G305: =IFERROR(VLOOKUP(E305,'(旧)ﾍﾞﾝﾀﾞｰ小型'!$A$3:$K$310,10,0),"") | H305: ⇒ | I305: =IFERROR(VLOOKUP(E305,'(新)ﾍﾞﾝﾀﾞｰ小型'!$A$3:$K$300,10,0),"")
A306: 305 | B306: =IFERROR(VLOOKUP(E306,'(新)ﾍﾞﾝﾀﾞｰ小型'!$A$3:$K$241,2,0), "") | C306: =IFERROR(VLOOKUP(E306,'(新)ﾍﾞﾝﾀﾞｰ小型'!$A$3:$K$300,4,0), "") | D306: =IFERROR(VLOOKUP(E306,'(新)ﾍﾞﾝﾀﾞｰ小型'!$A$3:$K$241,5,0), "") | E306: ='(新)ﾍﾞﾝﾀﾞｰ小型'!A307 -> TS13377388 | F306: =IFERROR(VLOOKUP(E306,'(新)ﾍﾞﾝﾀﾞｰ小型'!$A$3:$K$300,8,0), "") | G306: =IFERROR(VLOOKUP(E306,'(旧)ﾍﾞﾝﾀﾞｰ小型'!$A$3:$K$310,10,0),"") | H306: ⇒ | I306: =IFERROR(VLOOKUP(E306,'(新)ﾍﾞﾝﾀﾞｰ小型'!$A$3:$K$300,10,0),"")
A307: 306 | B307: =IFERROR(VLOOKUP(E307,'(新)ﾍﾞﾝﾀﾞｰ小型'!$A$3:$K$241,2,0), "") | C307: =IFERROR(VLOOKUP(E307,'(新)ﾍﾞﾝﾀﾞｰ小型'!$A$3:$K$300,4,0), "") | D307: =IFERROR(VLOOKUP(E307,'(新)ﾍﾞﾝﾀﾞｰ小型'!$A$3:$K$241,5,0), "") | E307: ='(新)ﾍﾞﾝﾀﾞｰ小型'!A308 -> TS13377387 | F307: =IFERROR(VLOOKUP(E307,'(新)ﾍﾞﾝﾀﾞｰ小型'!$A$3:$K$300,8,0), "") | G307: =IFERROR(VLOOKUP(E307,'(旧)ﾍﾞﾝﾀﾞｰ小型'!$A$3:$K$310,10,0),"") | H307: ⇒ | I307: =IFERROR(VLOOKUP(E307,'(新)ﾍﾞﾝﾀﾞｰ小型'!$A$3:$K$300,10,0),"")
A308: 307 | B308: =IFERROR(VLOOKUP(E308,'(新)ﾍﾞﾝﾀﾞｰ小型'!$A$3:$K$241,2,0), "") | C308: =IFERROR(VLOOKUP(E308,'(新)ﾍﾞﾝﾀﾞｰ小型'!$A$3:$K$300,4,0), "") | D308: =IFERROR(VLOOKUP(E308,'(新)ﾍﾞﾝﾀﾞｰ小型'!$A$3:$K$241,5,0), "") | E308: ='(新)ﾍﾞﾝﾀﾞｰ小型'!A309 -> 0 | F308: =IFERROR(VLOOKUP(E308,'(新)ﾍﾞﾝﾀﾞｰ小型'!$A$3:$K$300,8,0), "") | G308: =IFERROR(VLOOKUP(E308,'(旧)ﾍﾞﾝﾀﾞｰ小型'!$A$3:$K$310,10,0),"") | H308: ⇒ | I308: =IFERROR(VLOOKUP(E308,'(新)ﾍﾞﾝﾀﾞｰ小型'!$A$3:$K$300,10,0),"")
A309: 308 | B309: =IFERROR(VLOOKUP(E309,'(新)ﾍﾞﾝﾀﾞｰ小型'!$A$3:$K$241,2,0), "") | C309: =IFERROR(VLOOKUP(E309,'(新)ﾍﾞﾝﾀﾞｰ小型'!$A$3:$K$300,4,0), "") | D309: =IFERROR(VLOOKUP(E309,'(新)ﾍﾞﾝﾀﾞｰ小型'!$A$3:$K$241,5,0), "") | E309: ='(新)ﾍﾞﾝﾀﾞｰ小型'!A310 -> 0 | F309: =IFERROR(VLOOKUP(E309,'(新)ﾍﾞﾝﾀﾞｰ小型'!$A$3:$K$300,8,0), "") | G309: =IFERROR(VLOOKUP(E309,'(旧)ﾍﾞﾝﾀﾞｰ小型'!$A$3:$K$310,10,0),"") | H309: ⇒ | I309: =IFERROR(VLOOKUP(E309,'(新)ﾍﾞﾝﾀﾞｰ小型'!$A$3:$K$300,10,0),"")
A310: 309 | B310: =IFERROR(VLOOKUP(E310,'(新)ﾍﾞﾝﾀﾞｰ小型'!$A$3:$K$241,2,0), "") | C310: =IFERROR(VLOOKUP(E310,'(新)ﾍﾞﾝﾀﾞｰ小型'!$A$3:$K$300,4,0), "") | D310: =IFERROR(VLOOKUP(E310,'(新)ﾍﾞﾝﾀﾞｰ小型'!$A$3:$K$241,5,0), "") | E310: ='(新)ﾍﾞﾝﾀﾞｰ小型'!A311 -> 0 | F310: =IFERROR(VLOOKUP(E310,'(新)ﾍﾞﾝﾀﾞｰ小型'!$A$3:$K$300,8,0), "") | G310: =IFERROR(VLOOKUP(E310,'(旧)ﾍﾞﾝﾀﾞｰ小型'!$A$3:$K$310,10,0),"") | H310: ⇒ | I310: =IFERROR(VLOOKUP(E310,'(新)ﾍﾞﾝﾀﾞｰ小型'!$A$3:$K$300,10,0),"")
A311: 310 | B311: =IFERROR(VLOOKUP(E311,'(新)ﾍﾞﾝﾀﾞｰ小型'!$A$3:$K$241,2,0), "") | C311: =IFERROR(VLOOKUP(E311,'(新)ﾍﾞﾝﾀﾞｰ小型'!$A$3:$K$300,4,0), "") | D311: =IFERROR(VLOOKUP(E311,'(新)ﾍﾞﾝﾀﾞｰ小型'!$A$3:$K$241,5,0), "") | E311: ='(新)ﾍﾞﾝﾀﾞｰ小型'!A312 -> 0 | F311: =IFERROR(VLOOKUP(E311,'(新)ﾍﾞﾝﾀﾞｰ小型'!$A$3:$K$300,8,0), "") | G311: =IFERROR(VLOOKUP(E311,'(旧)ﾍﾞﾝﾀﾞｰ小型'!$A$3:$K$310,10,0),"") | H311: ⇒ | I311: =IFERROR(VLOOKUP(E311,'(新)ﾍﾞﾝﾀﾞｰ小型'!$A$3:$K$300,10,0),"")
A312: 311 | B312: =IFERROR(VLOOKUP(E312,'(新)ﾍﾞﾝﾀﾞｰ小型'!$A$3:$K$241,2,0), "") | C312: =IFERROR(VLOOKUP(E312,'(新)ﾍﾞﾝﾀﾞｰ小型'!$A$3:$K$300,4,0), "") | D312: =IFERROR(VLOOKUP(E312,'(新)ﾍﾞﾝﾀﾞｰ小型'!$A$3:$K$241,5,0), "") | E312: ='(新)ﾍﾞﾝﾀﾞｰ小型'!A313 -> 0 | F312: =IFERROR(VLOOKUP(E312,'(新)ﾍﾞﾝﾀﾞｰ小型'!$A$3:$K$241,8,0), "") | G312: =IFERROR(VLOOKUP(E312,'(旧)ﾍﾞﾝﾀﾞｰ小型'!$A$3:$K$310,10,0),"") | H312: ⇒ | I312: =IFERROR(VLOOKUP(E312,'(新)ﾍﾞﾝﾀﾞｰ小型'!$A$3:$K$300,10,0),"")
A313: 312 | B313: =IFERROR(VLOOKUP(E313,'(新)ﾍﾞﾝﾀﾞｰ小型'!$A$3:$K$241,2,0), "") | C313: =IFERROR(VLOOKUP(E313,'(新)ﾍﾞﾝﾀﾞｰ小型'!$A$3:$K$300,4,0), "") | D313: =IFERROR(VLOOKUP(E313,'(新)ﾍﾞﾝﾀﾞｰ小型'!$A$3:$K$241,5,0), "") | E313: ='(新)ﾍﾞﾝﾀﾞｰ小型'!A314 -> 0 | F313: =IFERROR(VLOOKUP(E313,'(新)ﾍﾞﾝﾀﾞｰ小型'!$A$3:$K$241,8,0), "") | G313: =IFERROR(VLOOKUP(E313,'(旧)ﾍﾞﾝﾀﾞｰ小型'!$A$3:$K$310,10,0),"") | H313: ⇒ | I313: =IFERROR(VLOOKUP(E313,'(新)ﾍﾞﾝﾀﾞｰ小型'!$A$3:$K$300,10,0),"")
A314: 313 | B314: =IFERROR(VLOOKUP(E314,'(新)ﾍﾞﾝﾀﾞｰ小型'!$A$3:$K$241,2,0), "") | C314: =IFERROR(VLOOKUP(E314,'(新)ﾍﾞﾝﾀﾞｰ小型'!$A$3:$K$300,4,0), "") | D314: =IFERROR(VLOOKUP(E314,'(新)ﾍﾞﾝﾀﾞｰ小型'!$A$3:$K$241,5,0), "") | E314: ='(新)ﾍﾞﾝﾀﾞｰ小型'!A315 -> 0 | F314: =IFERROR(VLOOKUP(E314,'(新)ﾍﾞﾝﾀﾞｰ小型'!$A$3:$K$241,8,0), "") | G314: =IFERROR(VLOOKUP(E314,'(旧)ﾍﾞﾝﾀﾞｰ小型'!$A$3:$K$310,10,0),"") | H314: ⇒ | I314: =IFERROR(VLOOKUP(E314,'(新)ﾍﾞﾝﾀﾞｰ小型'!$A$3:$K$300,10,0),"")
...

Sheet (旧)ﾍﾞﾝﾀﾞｰ中型
A1: Ｓｅｒ． | B1: 生産月 | C1: Ｎｏ． | D1: 機種名 | E1: 顧客 | F1: 仕様機種名 | G1: 仕様分類 | H1: 機種品番 | I1: 確定仕様書NO | J1: 着手日 | K1: 完成予定日
A3: HG22302236 | B3: 09月 | C3: 001 | D3: HG2203 | E3: （株）ミワレーザー | F3: HG2203-J | G3: STD | H3: 0F9373 | I3: 193742 | J3: 2026/08/01 | K3: 2026/08/21
A4: HG22448035 | B4: 09月 | C4: 002 | D4: HG2204ARM | E4: （株）徹工業 | F4: HG2204ARM-J | G4: STD | H4: 0A0837 | I4: ARm071 | J4: 2026/08/20 | K4: 2026/09/09
A5: HG22302244 | B5: 09月 | C5: 003 | D5: HG2203.EXP | E5: ＡＭＡＤＡ ＫＯＲＥＡ ＣＯ．，ＬＴＤ． | F5: HG2203-E | G5: STD | H5: 0F9378 | I5: ASB0897 | J5: 2026/08/20 | K5: 2026/09/02
A6: HG22402946 | B6: 09月 | C6: 004 | D6: HG2204 | E6: ナブコアール（株） | F6: HG2204-J | G6: STD | H6: 0F9374 | I6: 182967 | J6: 2026/08/25 | K6: 2026/09/05
A7: HG22404200 | B7: 09月 | C7: 005 | D7: HG2204ATC | E7: 安田技研（株） | F7: HG2204ATC-J | G7: STD | H7: 0F9375 | I7: 182681 | J7: 2026/08/25 | K7: 2026/09/15
A8: HG22402954 | B8: 09月 | C8: 006 | D8: HG2204.EXP | E8: ＡＭＡＤＡ ＣＡＮＡＤＡ ＬＴＤ． | F8: HG2204-E | G8: STD | H8: 0F9379 | I8: BDA1317 | J8: 2026/08/28 | K8: 2026/09/11
A9: HG22402956 | B9: 09月 | C9: 007 | D9: HG2204.EXP | E9: ＡＭＡＤＡ ＡＭＥＲＩＣＡ ＩＮＣ． | F9: HG2204-E | G9: STD | H9: 0F9379 | I9: BDA1310 | J9: 2026/08/28 | K9: 2026/09/11
A10: HG22404195 | B10: 09月 | C10: 008 | D10: HG2204ATC | E10: （株）廣澤精機製作所 | F10: HG2204ATC-J | G10: STD | H10: 0F9375 | I10: 182636 | J10: 2026/09/02 | K10: 2026/09/25
A11: HG22402952 | B11: 09月 | C11: 009 | D11: HG2204.EXP | E11: 【ACL】Metal Contracting | F11: HG2204-E | G11: STD | H11: 0F9379 | I11: BDA1318 | J11: 2026/09/02 | K11: 2026/09/16
A12: HG17302379 | B12: 09月 | C12: 010 | D12: HG1703 | E12: （株）ＴＩＳＭ | F12: HG1703-J | G12: STD | H12: 0F9262 | I12: 182695 | J12: 2026/09/04 | K12: 2026/09/18
A13: HG22402955 | B13: 09月 | C13: 011 | D13: HG2204.EXP | E13: ＡＭＡＤＡ ＡＭＥＲＩＣＡ ＩＮＣ． | F13: HG2204-E | G13: STD | H13: 0F9379 | I13: BDA1312 | J13: 2026/09/04 | K13: 2026/09/18
... A19: HG22402957 | B19: 10月 | C19: 003 | D19: HG2204.EXP | E19: Bao Tien Industrial Company | F19: HG2204-E | G19: STD | H19: 0F9379 | I19: APH0355 | J19: 2026/09/15 | K19: 2026/09/29
A20: HG22402961 | B20: 10月 | C20: 004 | D20: HG2204 | E20: （株）アマダベンディングＳ部 | F20: HG2204-J | G20: STD | H20: 0F9374 | J20: 2026/09/25 | K20: 2026/10/07
A21: HG22402962 | B21: 10月 | C21: 005 | D21: HG2204.EXP | E21: 【CHINA】Delta | F21: HG2204-E | G21: STD | H21: 0F9379 | I21: CN0463 | J21: 2026/09/30 | K21: 2026/10/10
A22: HG22402963 | B22: 10月 | C22: 006 | D22: HG2204.EXP | E22: 【CHINA】Delta | F22: HG2204-E | G22: STD | H22: 0F9379 | I22: CN0462 | J22: 2026/09/30 | K22: 2026/10/10
A23: HG22302246 | B23: 10月 | C23: 007 | D23: HG2203 | E23: ＩＭＣ（株） | F23: HG2203-J | G23: STD | H23: 0F9373 | I23: 194816 | J23: 2026/10/02 | K23: 2026/10/14
A24: HG22302247 | B24: 10月 | C24: 008 | D24: HG2203 | E24: （株）シンコー | F24: HG2203-J | G24: STD | H24: 0F9373 | I24: 194817 | J24: 2026/10/02 | K24: 2026/10/14
A25: HG17302383 | B25: 10月 | C25: 009 | D25: HG1703 | E25: （株）日立アイイーシステム | F25: HG1703-J | G25: STD | H25: 0F9262 | I25: 194845 | J25: 2026/10/10 | K25: 2026/10/23
A26: HG22402969 | B26: 10月 | C26: 010 | D26: HG2204.EXP | E26: ＡＭＡＤＡ ＡＭＥＲＩＣＡ ＩＮＣ． | F26: HG2204-E | G26: STD | H26: 0F9379 | I26: BDA1330 | J26: 2026/10/10 | K26: 2026/10/23
A27: HG22402970 | B27: 10月 | C27: 011 | D27: HG2204.EXP | E27: ＡＭＡＤＡ ＡＭＥＲＩＣＡ ＩＮＣ． | F27: HG2204-E | G27: STD | H27: 0F9379 | I27: BDA1331 | J27: 2026/10/14 | K27: 2026/10/27
A28: HG22402971 | B28: 10月 | C28: 012 | D28: HG2204.EXP | E28: ＡＭＡＤＡ ＣＡＮＡＤＡ ＬＴＤ． | F28: HG2204-E | G28: STD | H28: 0F9379 | I28: BDA1335 | J28: 2026/10/14 | K28: 2026/10/27
A29: HG22448036 | B29: 11月 | C29: 001 | D29: HG2204ARM | E29: （株）徹工業 | F29: HG2204ARM-J | G29: STD | H29: 0A0837 | I29: ARm072 | J29: 2026/10/23 | K29: 2026/11/11
A30: HG22402958 | B30: 11月 | C30: 002 | D30: HG2204.EXP | E30: 【OCEANIA】TEMPERZONE | F30: HG2204-E | G30: STD | H30: 0F9379 | I30: OCE0067 | J30: 2026/10/23 | K30: 2026/11/05
A31: HG22402964 | B31: 11月 | C31: 003 | D31: HG2204.EXP | E31: 【CHINA】Delta | F31: HG2204-E | G31: STD | H31: 0F9379 | I31: CN0464 | J31: 2026/10/28 | K31: 2026/11/09
A32: HG22402965 | B32: 11月 | C32: 004 | D32: HG2204.EXP | E32: 【CHINA】Delta | F32: HG2204-E | G32: STD | H32: 0F9379 | I32: CN0465 | J32: 2026/10/28 | K32: 2026/11/09
... A54: HG22404211 | B54: 01月 | C54: 001 | D54: HG2204ATC.EXP | E54: ＡＭＡＤＡ ＡＭＥＲＩＣＡ ＩＮＣ． | F54: HG2204ATC-E | G54: STD | H54: 0F9380 | I54: BDA1420 | J54: 2026/12/12 | K54: 2027/01/08
A55: HG17302387 | B55: 01月 | C55: 002 | D55: HG1703 | F55: HG1703-J | G55: STD | H55: 0F9262 | J55: 2026/12/16 | K55: 2027/01/05
A56: HG17402208 | B56: 01月 | C56: 003 | D56: HG1704 | F56: HG1704-J | G56: STD | H56: 0F9263 | J56: 2026/12/18 | K56: 2027/01/07
A57: HG22402983 | B57: 01月 | C57: 004 | D57: HG2204 | F57: HG2204-J | G57: STD | H57: 0F9374 | J57: 2026/12/22 | K57: 2027/01/09
A58: HG22402984 | B58: 01月 | C58: 005 | D58: HG2204 | F58: HG2204-J | G58: STD | H58: 0F9374 | J58: 2026/12/24 | K58: 2027/01/13
A59: HG22404210 | B59: 01月 | C59: 006 | D59: HG2204ATC | E59: （株）大明 | F59: HG2204ATC-J | G59: STD | H59: 0F9375 | I59: 2060400 | J59: 2026/12/26 | K59: 2027/01/22
A60: HG22402981 | B60: 01月 | C60: 007 | D60: HG2204.EXP | E60: 台湾 | F60: HG2204-E | G60: STD | H60: 0F9379 | J60: 2027/01/05 | K60: 2027/01/16
A61: HG22402982 | B61: 01月 | C61: 008 | D61: HG2204.EXP | E61: 【CHINA】北京埃鉑精密 | F61: HG2204-E | G61: STD | H61: 0F9379 | I61: CN0539 | J61: 2027/01/07 | K61: 2027/01/20
A62: HG22402986 | B62: 01月 | C62: 009 | D62: HG2204.EXP | E62: ＡＭＡＤＡ ＡＭＥＲＩＣＡ ＩＮＣ． | F62: HG2204-E | G62: STD | H62: 0F9379 | I62: BDA1418 | J62: 2027/01/09 | K62: 2027/01/22
A63: HG22402987 | B63: 01月 | C63: 010 | D63: HG2204.EXP | E63: ＡＭＡＤＡ ＡＭＥＲＩＣＡ ＩＮＣ． | F63: HG2204-E | G63: STD | H63: 0F9379 | I63: BDA1419 | J63: 2027/01/13 | K63: 2027/01/26
A64: HG22302250 | B64: 01月 | C64: 011 | D64: HG2203 | E64: 筑波工業（株） | F64: HG2203-J | G64: STD | H64: 0F9373 | I64: 194895 | J64: 2027/01/15 | K64: 2027/01/28
A65: HG17302386 | B65: 01月 | C65: 012 | D65: HG1703.EXP | E65: 【ACL】Greidy Labs | F65: HG1703-E | G65: STD | H65: 0F9376 | I65: BDA1437 | J65: 2027/01/19 | K65: 2027/01/30
A66: HG22404206 | B66: 02月 | C66: 001 | D66: HG2204ATC.EXP | E66: ＡＭＡＤＡ ＡＭＥＲＩＣＡ ＩＮＣ． | F66: HG2204ATC-E | G66: STD | H66: 0F9380 | I66: BDA1422 | J66: 2027/01/13 | K66: 2027/02/02
A67: HG22404207 | B67: 02月 | C67: 002 | D67: HG2204ATC.EXP | E67: ＡＭＡＤＡ ＡＭＥＲＩＣＡ ＩＮＣ． | F67: HG2204ATC-E | G67: STD | H67: 0F9380 | I67: BDA1423 | J67: 2027/01/15 | K67: 2027/02/04
...

Sheet (新)ﾍﾞﾝﾀﾞｰ中型
A1: Ｓｅｒ． | B1: 生産月 | C1: Ｎｏ． | D1: 機種名 | E1: 顧客 | F1: 仕様機種名 | G1: 仕様分類 | H1: 機種品番 | I1: 確定仕様書NO | J1: 着手日 | K1: 完成予定日
A3: HG22404200 | B3: 10月 | C3: 001 | D3: HG2204ATC | E3: 安田技研（株） | F3: HG2204ATC-J | G3: STD | H3: 0F9375 | I3: 182681 | J3: 2026/08/25 | K3: 2026/09/12
A4: HG22402954 | B4: 10月 | C4: 002 | D4: HG2204.EXP | E4: ＡＭＡＤＡ ＣＡＮＡＤＡ ＬＴＤ． | F4: HG2204-E | G4: STD | H4: 0F9379 | I4: BDA1317 | J4: 2026/08/28 | K4: 2026/09/09
A5: HG22402956 | B5: 10月 | C5: 003 | D5: HG2204.EXP | E5: ＡＭＡＤＡ ＡＭＥＲＩＣＡ ＩＮＣ． | F5: HG2204-E | G5: STD | H5: 0F9379 | I5: BDA1310 | J5: 2026/08/28 | K5: 2026/09/09
A6: HG22404195 | B6: 10月 | C6: 004 | D6: HG2204ATC | E6: （株）廣澤精機製作所 | F6: HG2204ATC-J | G6: STD | H6: 0F9375 | I6: 182636 | J6: 2026/09/02 | K6: 2026/09/19
A7: HG22402952 | B7: 10月 | C7: 005 | D7: HG2204.EXP | E7: 【ACL】Metal Contracting | F7: HG2204-E | G7: STD | H7: 0F9379 | I7: BDA1318 | J7: 2026/09/02 | K7: 2026/09/15
A8: HG22402955 | B8: 10月 | C8: 006 | D8: HG2204.EXP | E8: ＡＭＡＤＡ ＡＭＥＲＩＣＡ ＩＮＣ． | F8: HG2204-E | G8: STD | H8: 0F9379 | I8: BDA1312 | J8: 2026/09/04 | K8: 2026/09/17
A9: HG22448034 | B9: 10月 | C9: 007 | D9: HG2204ARM.EXP | E9: 【ブラジル】PERTO | F9: HG2204ARM-E | G9: STD | H9: 0A9529 | I9: BDH0537 | J9: 2026/09/08 | K9: 2026/09/29
A10: HG17302381 | B10: 10月 | C10: 008 | D10: HG1703.EXP | E10: 【ACL】Bercomac | F10: HG1703-E | G10: STD | H10: 0F9376 | I10: BDA1316 | J10: 2026/09/11 | K10: 2026/09/25
A11: HG22302245 | B11: 10月 | C11: 009 | D11: HG2203.EXP | E11: ＡＭＡＤＡ ＡＭＥＲＩＣＡ ＩＮＣ． | F11: HG2203-E | G11: STD | H11: 0F9378 | I11: BDA1311 | J11: 2026/09/12 | K11: 2026/09/26
A12: HG17402207 | B12: 10月 | C12: 010 | D12: HG1704 | E12: （株）平島 | F12: HG1704-J | G12: STD | H12: 0F9263 | I12: 182694 | J12: 2026/09/15 | K12: 2026/09/29
A13: HG22402957 | B13: 10月 | C13: 011 | D13: HG2204.EXP | E13: Bao Tien Industrial Company | F13: HG2204-E | G13: STD | H13: 0F9379 | I13: APH0355 | J13: 2026/09/15 | K13: 2026/09/29
A14: HG22402961 | B14: 10月 | C14: 012 | D14: HG2204 | E14: （株）アマダベンディングＳ部 | F14: HG2204-J | G14: STD | H14: 0F9374 | J14: 2026/09/25 | K14: 2026/10/07
A15: HG22402962 | B15: 10月 | C15: 013 | D15: HG2204.EXP | E15: 【CHINA】Delta | F15: HG2204-E | G15: STD | H15: 0F9379 | I15: CN0463 | J15: 2026/09/30 | K15: 2026/10/10
A16: HG22402963 | B16: 10月 | C16: 014 | D16: HG2204.EXP | E16: 【CHINA】Delta | F16: HG2204-E | G16: STD | H16: 0F9379 | I16: CN0462 | J16: 2026/09/30 | K16: 2026/10/10
A17: HG22302246 | B17: 10月 | C17: 015 | D17: HG2203 | E17: ＩＭＣ（株） | F17: HG2203-J | G17: STD | H17: 0F9373 | I17: 194816 | J17: 2026/10/02 | K17: 2026/10/14
A18: HG22302247 | B18: 10月 | C18: 016 | D18: HG2203 | E18: （株）シンコー | F18: HG2203-J | G18: STD | H18: 0F9373 | I18: 194817 | J18: 2026/10/02 | K18: 2026/10/14
A19: HG17302383 | B19: 10月 | C19: 017 | D19: HG1703 | E19: （株）日立アイイーシステム | F19: HG1703-J | G19: STD | H19: 0F9262 | I19: 194845 | J19: 2026/10/10 | K19: 2026/10/23
A20: HG22402969 | B20: 10月 | C20: 018 | D20: HG2204.EXP | E20: ＡＭＡＤＡ ＡＭＥＲＩＣＡ ＩＮＣ． | F20: HG2204-E | G20: STD | H20: 0F9379 | I20: BDA1330 | J20: 2026/10/10 | K20: 2026/10/23
A21: HG22402970 | B21: 10月 | C21: 019 | D21: HG2204.EXP | E21: ＡＭＡＤＡ ＡＭＥＲＩＣＡ ＩＮＣ． | F21: HG2204-E | G21: STD | H21: 0F9379 | I21: BDA1331 | J21: 2026/10/14 | K21: 2026/10/27
A22: HG22402971 | B22: 10月 | C22: 020 | D22: HG2204.EXP | E22: ＡＭＡＤＡ ＣＡＮＡＤＡ ＬＴＤ． | F22: HG2204-E | G22: STD | H22: 0F9379 | I22: BDA1335 | J22: 2026/10/14 | K22: 2026/10/27
A23: HG22448036 | B23: 11月 | C23: 001 | D23: HG2204ARM | E23: （株）徹工業 | F23: HG2204ARM-J | G23: STD | H23: 0A0837 | I23: ARm072 | J23: 2026/10/23 | K23: 2026/11/11
A24: HG22402958 | B24: 11月 | C24: 002 | D24: HG2204.EXP | E24: 【OCEANIA】TEMPERZONE | F24: HG2204-E | G24: STD | H24: 0F9379 | I24: OCE0067 | J24: 2026/10/23 | K24: 2026/11/05
A25: HG22402964 | B25: 11月 | C25: 003 | D25: HG2204.EXP | E25: 【CHINA】Delta | F25: HG2204-E | G25: STD | H25: 0F9379 | I25: CN0464 | J25: 2026/10/28 | K25: 2026/11/09
A26: HG22402965 | B26: 11月 | C26: 004 | D26: HG2204.EXP | E26: 【CHINA】Delta | F26: HG2204-E | G26: STD | H26: 0F9379 | I26: CN0465 | J26: 2026/10/28 | K26: 2026/11/09
... A50: HG22402982 | B50: 01月 | C50: 003 | D50: HG2204.EXP | E50: 【CHINA】北京埃鉑精密 | F50: HG2204-E | G50: STD | H50: 0F9379 | I50: CN0539 | J50: 2026/12/19 | K50: 2027/01/07
A51: HG17402208 | B51: 01月 | C51: 004 | D51: HG1704 | F51: HG1704-J | G51: STD | H51: 0F9263 | J51: 2026/12/23 | K51: 2027/01/09
A52: HG17302386 | B52: 01月 | C52: 005 | D52: HG1703.EXP | E52: 【ACL】Greidy Labs | F52: HG1703-E | G52: STD | H52: 0F9376 | I52: BDA1437 | J52: 2026/12/23 | K52: 2027/01/09
A53: HG22402983 | B53: 01月 | C53: 006 | D53: HG2204 | E53: マルマテクニカ（株） | F53: HG2204-J | G53: STD | H53: 0F9374 | I53: 206092 | J53: 2026/12/26 | K53: 2027/01/14
A54: HG22402986 | B54: 01月 | C54: 007 | D54: HG2204.EXP | E54: ＡＭＡＤＡ ＡＭＥＲＩＣＡ ＩＮＣ． | F54: HG2204-E | G54: STD | H54: 0F9379 | I54: BDA1418 | J54: 2026/12/26 | K54: 2027/01/14
A55: HG22402984 | B55: 01月 | C55: 008 | D55: HG2204 | E55: パナソニック ＨＶＡＣ ＆ ＣＣシステム | F55: HG2204-J | G55: STD | H55: 0F9374 | I55: 206091 | J55: 2027/01/06 | K55: 2027/01/16
A56: HG22402987 | B56: 01月 | C56: 009 | D56: HG2204.EXP | E56: ＡＭＡＤＡ ＡＭＥＲＩＣＡ ＩＮＣ． | F56: HG2204-E | G56: STD | H56: 0F9379 | I56: BDA1419 | J56: 2027/01/06 | K56: 2027/01/16
A57: HG22302250 | B57: 01月 | C57: 010 | D57: HG2203 | E57: 筑波工業（株） | F57: HG2203-J | G57: STD | H57: 0F9373 | I57: 194895 | J57: 2027/01/09 | K57: 2027/01/21
A58: HG22404210 | B58: 01月 | C58: 011 | D58: HG2204ATC | E58: （株）大明 | F58: HG2204ATC-J | G58: STD | H58: 0F9375 | I58: 2060400 | J58: 2027/01/09 | K58: 2027/01/27
A59: HG22402981 | B59: 01月 | C59: 012 | D59: HG2204.EXP | E59: 台湾 | F59: HG2204-E | G59: STD | H59: 0F9379 | J59: 2027/01/14 | K59: 2027/01/26
A60: HG22404206 | B60: 02月 | C60: 001 | D60: HG2204ATC.EXP | E60: ＡＭＡＤＡ ＡＭＥＲＩＣＡ ＩＮＣ． | F60: HG2204ATC-E | G60: STD | H60: 0F9380 | I60: BDA1422 | J60: 2027/01/15 | K60: 2027/02/02
A61: HG22404207 | B61: 02月 | C61: 002 | D61: HG2204ATC.EXP | E61: ＡＭＡＤＡ ＡＭＥＲＩＣＡ ＩＮＣ． | F61: HG2204ATC-E | G61: STD | H61: 0F9380 | I61: BDA1423 | J61: 2027/01/19 | K61: 2027/02/04
A62: HG22404205 | B62: 02月 | C62: 003 | D62: HG2204ATC.EXP | E62: ＡＭＡＤＡ ＡＭＥＲＩＣＡ ＩＮＣ． | F62: HG2204ATC-E | G62: STD | H62: 0F9380 | I62: BDA1421 | J62: 2027/01/22 | K62: 2027/02/09
A63: HG17302382 | B63: 02月 | C63: 004 | D63: HG1703 | E63: 東京キデン（株） | F63: HG1703-J | G63: STD | H63: 0F9262 | I63: 182689 | J63: 2027/01/23 | K63: 2027/02/04
A64: HG17302388 | B64: 02月 | C64: 005 | D64: HG1703 | E64: （株）中西製作所 | F64: HG1703-J | G64: STD | H64: 0F9262 | I64: 206077 | J64: 2027/01/27 | K64: 2027/02/06
...

Sheet ﾍﾞﾝﾀﾞｰ中型対照表
A1: NO | B1: 生産月 | C1: 機種名 | D1: 客先名 | E1: シリアルNo | F1: 機種品番 | G1: 着手日(変更前) | I1: 着手日(変更後)
A2: 1 | B2: =IFERROR(VLOOKUP(E2,'(新)ﾍﾞﾝﾀﾞｰ中型'!$A$3:$K$187,2,0),"") -> 10月 | C2: =IFERROR(VLOOKUP(E2,'(新)ﾍﾞﾝﾀﾞｰ中型'!$A$3:$K$187,4,0),"") -> HG2204ATC | D2: =IFERROR(VLOOKUP(E2,'(新)ﾍﾞﾝﾀﾞｰ中型'!$A$3:$K$187,5,0),"") -> 安田技研（株） | E2: ='(新)ﾍﾞﾝﾀﾞｰ中型'!A3 -> HG22404200 | F2: =IFERROR(VLOOKUP(E2,'(新)ﾍﾞﾝﾀﾞｰ中型'!$A$3:$K$187,8,0),"") -> 0F9375 | G2: =IFERROR(VLOOKUP(E2,'(旧)ﾍﾞﾝﾀﾞｰ中型'!$A$3:$K$200,10,0),"") -> 2026/08/25 | H2: ⇒ | I2: =IFERROR(VLOOKUP(E2,'(新)ﾍﾞﾝﾀﾞｰ中型'!$A$3:$K$187,10,0),"") -> 2026/08/25
A3: 2 | B3: =IFERROR(VLOOKUP(E3,'(新)ﾍﾞﾝﾀﾞｰ中型'!$A$3:$K$187,2,0),"") -> 10月 | C3: =IFERROR(VLOOKUP(E3,'(新)ﾍﾞﾝﾀﾞｰ中型'!$A$3:$K$187,4,0),"") -> HG2204.EXP | D3: =IFERROR(VLOOKUP(E3,'(新)ﾍﾞﾝﾀﾞｰ中型'!$A$3:$K$187,5,0),"") -> ＡＭＡＤＡ ＣＡＮＡＤＡ ＬＴＤ． | E3: ='(新)ﾍﾞﾝﾀﾞｰ中型'!A4 -> HG22402954 | F3: =IFERROR(VLOOKUP(E3,'(新)ﾍﾞﾝﾀﾞｰ中型'!$A$3:$K$187,8,0),"") -> 0F9379 | G3: =IFERROR(VLOOKUP(E3,'(旧)ﾍﾞﾝﾀﾞｰ中型'!$A$3:$K$200,10,0),"") -> 2026/08/28 | H3: ⇒ | I3: =IFERROR(VLOOKUP(E3,'(新)ﾍﾞﾝﾀﾞｰ中型'!$A$3:$K$187,10,0),"") -> 2026/08/28
A4: 3 | B4: =IFERROR(VLOOKUP(E4,'(新)ﾍﾞﾝﾀﾞｰ中型'!$A$3:$K$187,2,0),"") -> 10月 | C4: =IFERROR(VLOOKUP(E4,'(新)ﾍﾞﾝﾀﾞｰ中型'!$A$3:$K$187,4,0),"") -> HG2204.EXP | D4: =IFERROR(VLOOKUP(E4,'(新)ﾍﾞﾝﾀﾞｰ中型'!$A$3:$K$187,5,0),"") -> ＡＭＡＤＡ ＡＭＥＲＩＣＡ ＩＮＣ． | E4: ='(新)ﾍﾞﾝﾀﾞｰ中型'!A5 -> HG22402956 | F4: =IFERROR(VLOOKUP(E4,'(新)ﾍﾞﾝﾀﾞｰ中型'!$A$3:$K$187,8,0),"") -> 0F9379 | G4: =IFERROR(VLOOKUP(E4,'(旧)ﾍﾞﾝﾀﾞｰ中型'!$A$3:$K$200,10,0),"") -> 2026/08/28 | H4: ⇒ | I4: =IFERROR(VLOOKUP(E4,'(新)ﾍﾞﾝﾀﾞｰ中型'!$A$3:$K$187,10,0),"") -> 2026/08/28
A5: 4 | B5: =IFERROR(VLOOKUP(E5,'(新)ﾍﾞﾝﾀﾞｰ中型'!$A$3:$K$187,2,0),"") -> 10月 | C5: =IFERROR(VLOOKUP(E5,'(新)ﾍﾞﾝﾀﾞｰ中型'!$A$3:$K$187,4,0),"") -> HG2204ATC | D5: =IFERROR(VLOOKUP(E5,'(新)ﾍﾞﾝﾀﾞｰ中型'!$A$3:$K$187,5,0),"") -> （株）廣澤精機製作所 | E5: ='(新)ﾍﾞﾝﾀﾞｰ中型'!A6 -> HG22404195 | F5: =IFERROR(VLOOKUP(E5,'(新)ﾍﾞﾝﾀﾞｰ中型'!$A$3:$K$187,8,0),"") -> 0F9375 | G5: =IFERROR(VLOOKUP(E5,'(旧)ﾍﾞﾝﾀﾞｰ中型'!$A$3:$K$200,10,0),"") -> 2026/09/02 | H5: ⇒ | I5: =IFERROR(VLOOKUP(E5,'(新)ﾍﾞﾝﾀﾞｰ中型'!$A$3:$K$187,10,0),"") -> 2026/09/02
A6: 5 | B6: =IFERROR(VLOOKUP(E6,'(新)ﾍﾞﾝﾀﾞｰ中型'!$A$3:$K$187,2,0),"") -> 10月 | C6: =IFERROR(VLOOKUP(E6,'(新)ﾍﾞﾝﾀﾞｰ中型'!$A$3:$K$187,4,0),"") -> HG2204.EXP | D6: =IFERROR(VLOOKUP(E6,'(新)ﾍﾞﾝﾀﾞｰ中型'!$A$3:$K$187,5,0),"") -> 【ACL】Metal Contracting | E6: ='(新)ﾍﾞﾝﾀﾞｰ中型'!A7 -> HG22402952 | F6: =IFERROR(VLOOKUP(E6,'(新)ﾍﾞﾝﾀﾞｰ中型'!$A$3:$K$187,8,0),"") -> 0F9379 | G6: =IFERROR(VLOOKUP(E6,'(旧)ﾍﾞﾝﾀﾞｰ中型'!$A$3:$K$200,10,0),"") -> 2026/09/02 | H6: ⇒ | I6: =IFERROR(VLOOKUP(E6,'(新)ﾍﾞﾝﾀﾞｰ中型'!$A$3:$K$187,10,0),"") -> 2026/09/02
A7: 6 | B7: =IFERROR(VLOOKUP(E7,'(新)ﾍﾞﾝﾀﾞｰ中型'!$A$3:$K$187,2,0),"") -> 10月 | C7: =IFERROR(VLOOKUP(E7,'(新)ﾍﾞﾝﾀﾞｰ中型'!$A$3:$K$187,4,0),"") -> HG2204.EXP | D7: =IFERROR(VLOOKUP(E7,'(新)ﾍﾞﾝﾀﾞｰ中型'!$A$3:$K$187,5,0),"") -> ＡＭＡＤＡ ＡＭＥＲＩＣＡ ＩＮＣ． | E7: ='(新)ﾍﾞﾝﾀﾞｰ中型'!A8 -> HG22402955 | F7: =IFERROR(VLOOKUP(E7,'(新)ﾍﾞﾝﾀﾞｰ中型'!$A$3:$K$187,8,0),"") -> 0F9379 | G7: =IFERROR(VLOOKUP(E7,'(旧)ﾍﾞﾝﾀﾞｰ中型'!$A$3:$K$200,10,0),"") -> 2026/09/04 | H7: ⇒ | I7: =IFERROR(VLOOKUP(E7,'(新)ﾍﾞﾝﾀﾞｰ中型'!$A$3:$K$187,10,0),"") -> 2026/09/04
A8: 7 | B8: =IFERROR(VLOOKUP(E8,'(新)ﾍﾞﾝﾀﾞｰ中型'!$A$3:$K$187,2,0),"") -> 10月 | C8: =IFERROR(VLOOKUP(E8,'(新)ﾍﾞﾝﾀﾞｰ中型'!$A$3:$K$187,4,0),"") -> HG2204ARM.EXP | D8: =IFERROR(VLOOKUP(E8,'(新)ﾍﾞﾝﾀﾞｰ中型'!$A$3:$K$187,5,0),"") -> 【ブラジル】PERTO | E8: ='(新)ﾍﾞﾝﾀﾞｰ中型'!A9 -> HG22448034 | F8: =IFERROR(VLOOKUP(E8,'(新)ﾍﾞﾝﾀﾞｰ中型'!$A$3:$K$187,8,0),"") -> 0A9529 | G8: =IFERROR(VLOOKUP(E8,'(旧)ﾍﾞﾝﾀﾞｰ中型'!$A$3:$K$200,10,0),"") -> 2026/09/08 | H8: ⇒ | I8: =IFERROR(VLOOKUP(E8,'(新)ﾍﾞﾝﾀﾞｰ中型'!$A$3:$K$187,10,0),"") -> 2026/09/08
A9: 8 | B9: =IFERROR(VLOOKUP(E9,'(新)ﾍﾞﾝﾀﾞｰ中型'!$A$3:$K$187,2,0),"") -> 10月 | C9: =IFERROR(VLOOKUP(E9,'(新)ﾍﾞﾝﾀﾞｰ中型'!$A$3:$K$187,4,0),"") -> HG1703.EXP | D9: =IFERROR(VLOOKUP(E9,'(新)ﾍﾞﾝﾀﾞｰ中型'!$A$3:$K$187,5,0),"") -> 【ACL】Bercomac | E9: ='(新)ﾍﾞﾝﾀﾞｰ中型'!A10 -> HG17302381 | F9: =IFERROR(VLOOKUP(E9,'(新)ﾍﾞﾝﾀﾞｰ中型'!$A$3:$K$187,8,0),"") -> 0F9376 | G9: =IFERROR(VLOOKUP(E9,'(旧)ﾍﾞﾝﾀﾞｰ中型'!$A$3:$K$200,10,0),"") -> 2026/09/11 | H9: ⇒ | I9: =IFERROR(VLOOKUP(E9,'(新)ﾍﾞﾝﾀﾞｰ中型'!$A$3:$K$187,10,0),"") -> 2026/09/11
A10: 9 | B10: =IFERROR(VLOOKUP(E10,'(新)ﾍﾞﾝﾀﾞｰ中型'!$A$3:$K$187,2,0),"") -> 10月 | C10: =IFERROR(VLOOKUP(E10,'(新)ﾍﾞﾝﾀﾞｰ中型'!$A$3:$K$187,4,0),"") -> HG2203.EXP | D10: =IFERROR(VLOOKUP(E10,'(新)ﾍﾞﾝﾀﾞｰ中型'!$A$3:$K$187,5,0),"") -> ＡＭＡＤＡ ＡＭＥＲＩＣＡ ＩＮＣ． | E10: ='(新)ﾍﾞﾝﾀﾞｰ中型'!A11 -> HG22302245 | F10: =IFERROR(VLOOKUP(E10,'(新)ﾍﾞﾝﾀﾞｰ中型'!$A$3:$K$187,8,0),"") -> 0F9378 | G10: =IFERROR(VLOOKUP(E10,'(旧)ﾍﾞﾝﾀﾞｰ中型'!$A$3:$K$200,10,0),"") -> 2026/09/12 | H10: ⇒ | I10: =IFERROR(VLOOKUP(E10,'(新)ﾍﾞﾝﾀﾞｰ中型'!$A$3:$K$187,10,0),"") -> 2026/09/12
A11: 10 | B11: =IFERROR(VLOOKUP(E11,'(新)ﾍﾞﾝﾀﾞｰ中型'!$A$3:$K$187,2,0),"") -> 10月 | C11: =IFERROR(VLOOKUP(E11,'(新)ﾍﾞﾝﾀﾞｰ中型'!$A$3:$K$187,4,0),"") -> HG1704 | D11: =IFERROR(VLOOKUP(E11,'(新)ﾍﾞﾝﾀﾞｰ中型'!$A$3:$K$187,5,0),"") -> （株）平島 | E11: ='(新)ﾍﾞﾝﾀﾞｰ中型'!A12 -> HG17402207 | F11: =IFERROR(VLOOKUP(E11,'(新)ﾍﾞﾝﾀﾞｰ中型'!$A$3:$K$187,8,0),"") -> 0F9263 | G11: =IFERROR(VLOOKUP(E11,'(旧)ﾍﾞﾝﾀﾞｰ中型'!$A$3:$K$200,10,0),"") -> 2026/09/15 | H11: ⇒ | I11: =IFERROR(VLOOKUP(E11,'(新)ﾍﾞﾝﾀﾞｰ中型'!$A$3:$K$187,10,0),"") -> 2026/09/15
A12: 11 | B12: =IFERROR(VLOOKUP(E12,'(新)ﾍﾞﾝﾀﾞｰ中型'!$A$3:$K$187,2,0),"") -> 10月 | C12: =IFERROR(VLOOKUP(E12,'(新)ﾍﾞﾝﾀﾞｰ中型'!$A$3:$K$187,4,0),"") -> HG2204.EXP | D12: =IFERROR(VLOOKUP(E12,'(新)ﾍﾞﾝﾀﾞｰ中型'!$A$3:$K$187,5,0),"") -> Bao Tien Industrial Company | E12: ='(新)ﾍﾞﾝﾀﾞｰ中型'!A13 -> HG22402957 | F12: =IFERROR(VLOOKUP(E12,'(新)ﾍﾞﾝﾀﾞｰ中型'!$A$3:$K$187,8,0),"") -> 0F9379 | G12: =IFERROR(VLOOKUP(E12,'(旧)ﾍﾞﾝﾀﾞｰ中型'!$A$3:$K$200,10,0),"") -> 2026/09/15 | H12: ⇒ | I12: =IFERROR(VLOOKUP(E12,'(新)ﾍﾞﾝﾀﾞｰ中型'!$A$3:$K$187,10,0),"") -> 2026/09/15
A13: 12 | B13: =IFERROR(VLOOKUP(E13,'(新)ﾍﾞﾝﾀﾞｰ中型'!$A$3:$K$187,2,0),"") -> 10月 | C13: =IFERROR(VLOOKUP(E13,'(新)ﾍﾞﾝﾀﾞｰ中型'!$A$3:$K$187,4,0),"") -> HG2204 | D13: =IFERROR(VLOOKUP(E13,'(新)ﾍﾞﾝﾀﾞｰ中型'!$A$3:$K$187,5,0),"") -> （株）アマダベンディングＳ部 | E13: ='(新)ﾍﾞﾝﾀﾞｰ中型'!A14 -> HG22402961 | F13: =IFERROR(VLOOKUP(E13,'(新)ﾍﾞﾝﾀﾞｰ中型'!$A$3:$K$187,8,0),"") -> 0F9374 | G13: =IFERROR(VLOOKUP(E13,'(旧)ﾍﾞﾝﾀﾞｰ中型'!$A$3:$K$200,10,0),"") -> 2026/09/25 | H13: ⇒ | I13: =IFERROR(VLOOKUP(E13,'(新)ﾍﾞﾝﾀﾞｰ中型'!$A$3:$K$187,10,0),"") -> 2026/09/25
... A130: 129 | B130: =IFERROR(VLOOKUP(E130,'(新)ﾍﾞﾝﾀﾞｰ中型'!$A$3:$K$187,2,0),"") | C130: =IFERROR(VLOOKUP(E130,'(新)ﾍﾞﾝﾀﾞｰ中型'!$A$3:$K$187,4,0),"") | D130: =IFERROR(VLOOKUP(E130,'(新)ﾍﾞﾝﾀﾞｰ中型'!$A$3:$K$187,5,0),"") | E130: ='(新)ﾍﾞﾝﾀﾞｰ中型'!A131 -> 0 | F130: =IFERROR(VLOOKUP(E130,'(新)ﾍﾞﾝﾀﾞｰ中型'!$A$3:$K$187,8,0),"") | G130: =IFERROR(VLOOKUP(E130,'(旧)ﾍﾞﾝﾀﾞｰ中型'!$A$3:$K$200,10,0),"") | H130: ⇒ | I130: =IFERROR(VLOOKUP(E130,'(新)ﾍﾞﾝﾀﾞｰ中型'!$A$3:$K$187,10,0),"")
A131: 130 | B131: =IFERROR(VLOOKUP(E131,'(新)ﾍﾞﾝﾀﾞｰ中型'!$A$3:$K$187,2,0),"") | C131: =IFERROR(VLOOKUP(E131,'(新)ﾍﾞﾝﾀﾞｰ中型'!$A$3:$K$187,4,0),"") | D131: =IFERROR(VLOOKUP(E131,'(新)ﾍﾞﾝﾀﾞｰ中型'!$A$3:$K$187,5,0),"") | E131: ='(新)ﾍﾞﾝﾀﾞｰ中型'!A119 -> 0 | F131: =IFERROR(VLOOKUP(E131,'(新)ﾍﾞﾝﾀﾞｰ中型'!$A$3:$K$187,8,0),"") | G131: =IFERROR(VLOOKUP(E131,'(旧)ﾍﾞﾝﾀﾞｰ中型'!$A$3:$K$200,10,0),"") | H131: ⇒ | I131: =IFERROR(VLOOKUP(E131,'(新)ﾍﾞﾝﾀﾞｰ中型'!$A$3:$K$187,10,0),"")
A132: 131 | B132: =IFERROR(VLOOKUP(E132,'(新)ﾍﾞﾝﾀﾞｰ中型'!$A$3:$K$187,2,0),"") | C132: =IFERROR(VLOOKUP(E132,'(新)ﾍﾞﾝﾀﾞｰ中型'!$A$3:$K$187,4,0),"") | D132: =IFERROR(VLOOKUP(E132,'(新)ﾍﾞﾝﾀﾞｰ中型'!$A$3:$K$187,5,0),"") | E132: ='(新)ﾍﾞﾝﾀﾞｰ中型'!A120 -> 0 | F132: =IFERROR(VLOOKUP(E132,'(新)ﾍﾞﾝﾀﾞｰ中型'!$A$3:$K$187,8,0),"") | G132: =IFERROR(VLOOKUP(E132,'(旧)ﾍﾞﾝﾀﾞｰ中型'!$A$3:$K$200,10,0),"") | H132: ⇒ | I132: =IFERROR(VLOOKUP(E132,'(新)ﾍﾞﾝﾀﾞｰ中型'!$A$3:$K$187,10,0),"")
A133: 132 | B133: =IFERROR(VLOOKUP(E133,'(新)ﾍﾞﾝﾀﾞｰ中型'!$A$3:$K$187,2,0),"") | C133: =IFERROR(VLOOKUP(E133,'(新)ﾍﾞﾝﾀﾞｰ中型'!$A$3:$K$187,4,0),"") | D133: =IFERROR(VLOOKUP(E133,'(新)ﾍﾞﾝﾀﾞｰ中型'!$A$3:$K$187,5,0),"") | E133: ='(新)ﾍﾞﾝﾀﾞｰ中型'!A121 -> 0 | F133: =IFERROR(VLOOKUP(E133,'(新)ﾍﾞﾝﾀﾞｰ中型'!$A$3:$K$187,8,0),"") | G133: =IFERROR(VLOOKUP(E133,'(旧)ﾍﾞﾝﾀﾞｰ中型'!$A$3:$K$200,10,0),"") | H133: ⇒ | I133: =IFERROR(VLOOKUP(E133,'(新)ﾍﾞﾝﾀﾞｰ中型'!$A$3:$K$187,10,0),"")
A134: 133 | B134: =IFERROR(VLOOKUP(E134,'(新)ﾍﾞﾝﾀﾞｰ中型'!$A$3:$K$187,2,0),"") | C134: =IFERROR(VLOOKUP(E134,'(新)ﾍﾞﾝﾀﾞｰ中型'!$A$3:$K$187,4,0),"") | D134: =IFERROR(VLOOKUP(E134,'(新)ﾍﾞﾝﾀﾞｰ中型'!$A$3:$K$187,5,0),"") | E134: ='(新)ﾍﾞﾝﾀﾞｰ中型'!A122 -> 0 | F134: =IFERROR(VLOOKUP(E134,'(新)ﾍﾞﾝﾀﾞｰ中型'!$A$3:$K$187,8,0),"") | G134: =IFERROR(VLOOKUP(E134,'(旧)ﾍﾞﾝﾀﾞｰ中型'!$A$3:$K$200,10,0),"") | H134: ⇒ | I134: =IFERROR(VLOOKUP(E134,'(新)ﾍﾞﾝﾀﾞｰ中型'!$A$3:$K$187,10,0),"")
A135: 134 | B135: =IFERROR(VLOOKUP(E135,'(新)ﾍﾞﾝﾀﾞｰ中型'!$A$3:$K$187,2,0),"") | C135: =IFERROR(VLOOKUP(E135,'(新)ﾍﾞﾝﾀﾞｰ中型'!$A$3:$K$187,4,0),"") | D135: =IFERROR(VLOOKUP(E135,'(新)ﾍﾞﾝﾀﾞｰ中型'!$A$3:$K$187,5,0),"") | E135: ='(新)ﾍﾞﾝﾀﾞｰ中型'!A123 -> 0 | F135: =IFERROR(VLOOKUP(E135,'(新)ﾍﾞﾝﾀﾞｰ中型'!$A$3:$K$187,8,0),"") | G135: =IFERROR(VLOOKUP(E135,'(旧)ﾍﾞﾝﾀﾞｰ中型'!$A$3:$K$200,10,0),"") | H135: ⇒ | I135: =IFERROR(VLOOKUP(E135,'(新)ﾍﾞﾝﾀﾞｰ中型'!$A$3:$K$187,10,0),"")
A136: 135 | B136: =IFERROR(VLOOKUP(E136,'(新)ﾍﾞﾝﾀﾞｰ中型'!$A$3:$K$187,2,0),"") | C136: =IFERROR(VLOOKUP(E136,'(新)ﾍﾞﾝﾀﾞｰ中型'!$A$3:$K$187,4,0),"") | D136: =IFERROR(VLOOKUP(E136,'(新)ﾍﾞﾝﾀﾞｰ中型'!$A$3:$K$187,5,0),"") | E136: ='(新)ﾍﾞﾝﾀﾞｰ中型'!A124 -> 0 | F136: =IFERROR(VLOOKUP(E136,'(新)ﾍﾞﾝﾀﾞｰ中型'!$A$3:$K$187,8,0),"") | G136: =IFERROR(VLOOKUP(E136,'(旧)ﾍﾞﾝﾀﾞｰ中型'!$A$3:$K$200,10,0),"") | H136: ⇒ | I136: =IFERROR(VLOOKUP(E136,'(新)ﾍﾞﾝﾀﾞｰ中型'!$A$3:$K$187,10,0),"")
A137: 136 | B137: =IFERROR(VLOOKUP(E137,'(新)ﾍﾞﾝﾀﾞｰ中型'!$A$3:$K$187,2,0),"") | C137: =IFERROR(VLOOKUP(E137,'(新)ﾍﾞﾝﾀﾞｰ中型'!$A$3:$K$187,4,0),"") | D137: =IFERROR(VLOOKUP(E137,'(新)ﾍﾞﾝﾀﾞｰ中型'!$A$3:$K$187,5,0),"") | E137: ='(新)ﾍﾞﾝﾀﾞｰ中型'!A125 -> 0 | F137: =IFERROR(VLOOKUP(E137,'(新)ﾍﾞﾝﾀﾞｰ中型'!$A$3:$K$187,8,0),"") | G137: =IFERROR(VLOOKUP(E137,'(旧)ﾍﾞﾝﾀﾞｰ中型'!$A$3:$K$200,10,0),"") | H137: ⇒ | I137: =IFERROR(VLOOKUP(E137,'(新)ﾍﾞﾝﾀﾞｰ中型'!$A$3:$K$187,10,0),"")
A138: 137 | B138: =IFERROR(VLOOKUP(E138,'(新)ﾍﾞﾝﾀﾞｰ中型'!$A$3:$K$187,2,0),"") | C138: =IFERROR(VLOOKUP(E138,'(新)ﾍﾞﾝﾀﾞｰ中型'!$A$3:$K$187,4,0),"") | D138: =IFERROR(VLOOKUP(E138,'(新)ﾍﾞﾝﾀﾞｰ中型'!$A$3:$K$187,5,0),"") | E138: ='(新)ﾍﾞﾝﾀﾞｰ中型'!A126 -> 0 | F138: =IFERROR(VLOOKUP(E138,'(新)ﾍﾞﾝﾀﾞｰ中型'!$A$3:$K$187,8,0),"") | G138: =IFERROR(VLOOKUP(E138,'(旧)ﾍﾞﾝﾀﾞｰ中型'!$A$3:$K$200,10,0),"") | H138: ⇒ | I138: =IFERROR(VLOOKUP(E138,'(新)ﾍﾞﾝﾀﾞｰ中型'!$A$3:$K$187,10,0),"")
A139: 138 | B139: =IFERROR(VLOOKUP(E139,'(新)ﾍﾞﾝﾀﾞｰ中型'!$A$3:$K$187,2,0),"") | C139: =IFERROR(VLOOKUP(E139,'(新)ﾍﾞﾝﾀﾞｰ中型'!$A$3:$K$187,4,0),"") | D139: =IFERROR(VLOOKUP(E139,'(新)ﾍﾞﾝﾀﾞｰ中型'!$A$3:$K$187,5,0),"") | E139: ='(新)ﾍﾞﾝﾀﾞｰ中型'!A127 -> 0 | F139: =IFERROR(VLOOKUP(E139,'(新)ﾍﾞﾝﾀﾞｰ中型'!$A$3:$K$187,8,0),"") | G139: =IFERROR(VLOOKUP(E139,'(旧)ﾍﾞﾝﾀﾞｰ中型'!$A$3:$K$200,10,0),"") | H139: ⇒ | I139: =IFERROR(VLOOKUP(E139,'(新)ﾍﾞﾝﾀﾞｰ中型'!$A$3:$K$187,10,0),"")
A140: 139 | B140: =IFERROR(VLOOKUP(E140,'(新)ﾍﾞﾝﾀﾞｰ中型'!$A$3:$K$187,2,0),"") | C140: =IFERROR(VLOOKUP(E140,'(新)ﾍﾞﾝﾀﾞｰ中型'!$A$3:$K$187,4,0),"") | D140: =IFERROR(VLOOKUP(E140,'(新)ﾍﾞﾝﾀﾞｰ中型'!$A$3:$K$187,5,0),"") | E140: ='(新)ﾍﾞﾝﾀﾞｰ中型'!A128 -> 0 | F140: =IFERROR(VLOOKUP(E140,'(新)ﾍﾞﾝﾀﾞｰ中型'!$A$3:$K$187,8,0),"") | G140: =IFERROR(VLOOKUP(E140,'(旧)ﾍﾞﾝﾀﾞｰ中型'!$A$3:$K$200,10,0),"") | H140: ⇒ | I140: =IFERROR(VLOOKUP(E140,'(新)ﾍﾞﾝﾀﾞｰ中型'!$A$3:$K$187,10,0),"")
A141: 140 | B141: =IFERROR(VLOOKUP(E141,'(新)ﾍﾞﾝﾀﾞｰ中型'!$A$3:$K$187,2,0),"") | C141: =IFERROR(VLOOKUP(E141,'(新)ﾍﾞﾝﾀﾞｰ中型'!$A$3:$K$187,4,0),"") | D141: =IFERROR(VLOOKUP(E141,'(新)ﾍﾞﾝﾀﾞｰ中型'!$A$3:$K$187,5,0),"") | E141: ='(新)ﾍﾞﾝﾀﾞｰ中型'!A129 -> 0 | F141: =IFERROR(VLOOKUP(E141,'(新)ﾍﾞﾝﾀﾞｰ中型'!$A$3:$K$187,8,0),"") | G141: =IFERROR(VLOOKUP(E141,'(旧)ﾍﾞﾝﾀﾞｰ中型'!$A$3:$K$200,10,0),"") | H141: ⇒ | I141: =IFERROR(VLOOKUP(E141,'(新)ﾍﾞﾝﾀﾞｰ中型'!$A$3:$K$187,10,0),"")
A142: 141 | B142: =IFERROR(VLOOKUP(E142,'(新)ﾍﾞﾝﾀﾞｰ中型'!$A$3:$K$187,2,0),"") | C142: =IFERROR(VLOOKUP(E142,'(新)ﾍﾞﾝﾀﾞｰ中型'!$A$3:$K$187,4,0),"") | D142: =IFERROR(VLOOKUP(E142,'(新)ﾍﾞﾝﾀﾞｰ中型'!$A$3:$K$187,5,0),"") | E142: ='(新)ﾍﾞﾝﾀﾞｰ中型'!A130 -> 0 | F142: =IFERROR(VLOOKUP(E142,'(新)ﾍﾞﾝﾀﾞｰ中型'!$A$3:$K$187,8,0),"") | G142: =IFERROR(VLOOKUP(E142,'(旧)ﾍﾞﾝﾀﾞｰ中型'!$A$3:$K$200,10,0),"") | H142: ⇒ | I142: =IFERROR(VLOOKUP(E142,'(新)ﾍﾞﾝﾀﾞｰ中型'!$A$3:$K$187,10,0),"")
... A200: 199 | B200: =IFERROR(VLOOKUP(E200,'(新)ﾍﾞﾝﾀﾞｰ中型'!$A$3:$K$187,2,0),"") | C200: =IFERROR(VLOOKUP(E200,'(新)ﾍﾞﾝﾀﾞｰ中型'!$A$3:$K$187,4,0),"") | D200: =IFERROR(VLOOKUP(E200,'(新)ﾍﾞﾝﾀﾞｰ中型'!$A$3:$K$187,5,0),"") | E200: ='(新)ﾍﾞﾝﾀﾞｰ中型'!A188 -> 0 | F200: =IFERROR(VLOOKUP(E200,'(新)ﾍﾞﾝﾀﾞｰ中型'!$A$3:$K$187,8,0),"") | G200: =IFERROR(VLOOKUP(E200,'(旧)ﾍﾞﾝﾀﾞｰ中型'!$A$3:$K$200,10,0),"") | H200: ⇒ | I200: =IFERROR(VLOOKUP(E200,'(新)ﾍﾞﾝﾀﾞｰ中型'!$A$3:$K$187,10,0),"")
A201: 200 | C201: =IFERROR(VLOOKUP(E201,'(新)ﾍﾞﾝﾀﾞｰ中型'!$A$3:$K$81,4,0),"") | D201: =IFERROR(VLOOKUP(E201,'(新)ﾍﾞﾝﾀﾞｰ中型'!$A$3:$K$87,5,0),"") | E201: ='(新)ﾍﾞﾝﾀﾞｰ中型'!A189 -> 0 | F201: =IFERROR(VLOOKUP(E201,'(新)ﾍﾞﾝﾀﾞｰ中型'!$A$3:$K$81,8,0),"") | G201: =IFERROR(VLOOKUP(E201,'(旧)ﾍﾞﾝﾀﾞｰ中型'!$A$3:$K$237,10,0),"") | H201: ⇒ | I201: =IFERROR(VLOOKUP(E201,'(新)ﾍﾞﾝﾀﾞｰ中型'!$A$3:$K$81,10,0),"")
C202: =IFERROR(VLOOKUP(E202,'(新)ﾍﾞﾝﾀﾞｰ中型'!$A$3:$K$81,4,0),"") | D202: =IFERROR(VLOOKUP(E202,'(新)ﾍﾞﾝﾀﾞｰ中型'!$A$3:$K$87,5,0),"") | E202: ='(新)ﾍﾞﾝﾀﾞｰ中型'!A190 -> 0 | F202: =IFERROR(VLOOKUP(E202,'(新)ﾍﾞﾝﾀﾞｰ中型'!$A$3:$K$81,8,0),"") | G202: =IFERROR(VLOOKUP(E202,'(旧)ﾍﾞﾝﾀﾞｰ中型'!$A$3:$K$237,10,0),"") | H202: ⇒ | I202: =IFERROR(VLOOKUP(E202,'(新)ﾍﾞﾝﾀﾞｰ中型'!$A$3:$K$81,10,0),"")
C203: =IFERROR(VLOOKUP(E203,'(新)ﾍﾞﾝﾀﾞｰ中型'!$A$3:$K$81,4,0),"") | D203: =IFERROR(VLOOKUP(E203,'(新)ﾍﾞﾝﾀﾞｰ中型'!$A$3:$K$87,5,0),"") | F203: =IFERROR(VLOOKUP(E203,'(新)ﾍﾞﾝﾀﾞｰ中型'!$A$3:$K$81,8,0),"") | G203: =IFERROR(VLOOKUP(E203,'(旧)ﾍﾞﾝﾀﾞｰ中型'!$A$3:$K$237,10,0),"") | H203: ⇒ | I203: =IFERROR(VLOOKUP(E203,'(新)ﾍﾞﾝﾀﾞｰ中型'!$A$3:$K$81,10,0),"")
C204: =IFERROR(VLOOKUP(E204,'(新)ﾍﾞﾝﾀﾞｰ中型'!$A$3:$K$81,4,0),"") | D204: =IFERROR(VLOOKUP(E204,'(新)ﾍﾞﾝﾀﾞｰ中型'!$A$3:$K$87,5,0),"") | F204: =IFERROR(VLOOKUP(E204,'(新)ﾍﾞﾝﾀﾞｰ中型'!$A$3:$K$81,8,0),"") | G204: =IFERROR(VLOOKUP(E204,'(旧)ﾍﾞﾝﾀﾞｰ中型'!$A$3:$K$237,10,0),"") | H204: ⇒ | I204: =IFERROR(VLOOKUP(E204,'(新)ﾍﾞﾝﾀﾞｰ中型'!$A$3:$K$81,10,0),"")
